Workbook

Sheet Investor Dashboard
A1: Constistant — Investor Dashboard
A2: สรุปตัวเลกสำหรับนักลงทุน — ทุกช่องเป็นสูตรอ้างอิง คลิกเลขใดๆเพื่อดูที่มาจริง
A4: 1. ราคา & ROI ที่ลูกค้าได้จริง ต่อไซส์
A5: รายการ | B5: Small | C5: Medium | D5: ใหญ่ | E5: Blended | F5: ที่มา/สูตร
A6: ราคา SaaS (บาท/เดือน) | B6: ='Client — Summary'!$B$12 -> 5000 | C6: ='Client — Summary'!$C$12 -> 7000 | D6: ='Client — Summary'!$D$12 -> 12000 | E6: ='Client — Summary'!$E$12 -> 6550 | F6: Client — Summary!B12:E12
A7: ROI ที่ลูกค้าได้ (มูลค่า ÷ ราคา) | B7: ='Client — Summary'!$B$9 -> 1.0019864 | C7: ='Client — Summary'!$C$9 -> 5.0727031 | D7: ='Client — Summary'!$D$9 -> 5.2150286 | E7: ='Client — Summary'!$E$9 -> 2.6516219 | F7: ⚠️ Small ≈ 1.0x — ดู Pricing Strategy!A18 สำหรับคำเตือน
A8: AI COGS Gross Margin (หลังหักเฉพาะต้นทุน AI) | B8: ='AI Infra — Unit Cost'!$B$23 -> 0.98125 | C8: ='AI Infra — Unit Cost'!$C$23 -> 0.91071429 | D8: ='AI Infra — Unit Cost'!$D$23 -> 0.89583333 | F8: AI Infra — Unit Cost!B23:D23 — ยังไม่รวม team/hosting/CAC
A10: 2. ลูกค้าสะสม & รายได้ — 5 ปี (Base Case)
A11: รายการ | B11: ปี 1 | C11: ปี 2 | D11: ปี 3 | E11: ปี 4 | F11: ปี 5
A12: ลูกค้าสะสม (ราย) | B12: ='5-Year Projection'!$B$6 -> 1086 | C12: ='5-Year Projection'!$C$6 -> 2015 | D12: ='5-Year Projection'!$D$6 -> 2810 | E12: ='5-Year Projection'!$E$6 -> 5620 | F12: ='5-Year Projection'!$F$6 -> 11240
A13: → รายได้ (ARR, บาท) | B13: ='5-Year Projection'!$B$11 -> 44191512 | C13: ='5-Year Projection'!$C$11 -> 102583650 | D13: ='5-Year Projection'!$D$11 -> 220866000 | E13: ='5-Year Projection'!$E$11 -> 472080000 | F13: ='5-Year Projection'!$F$11 -> 991368000
A14: → % Net Margin | B14: ='5-Year Projection'!$B$24 -> 0.81290355 | C14: ='5-Year Projection'!$C$24 -> 0.88188268 | D14: ='5-Year Projection'!$D$24 -> 0.91411535 | E14: ='5-Year Projection'!$E$24 -> 0.89983001 | F14: ='5-Year Projection'!$F$24 -> 0.89673436
A16: ต้นปี 3 เทียบ 3 Scenario (ลูกค้า/รายได้, ARR) | B16: Worst | C16: Base | D16: Best
A17: ลูกค้า / รายได้ | B17: ='5-Year Projection'!$D$5&" ราย / "&TEXT('5-Year Projection'!$D$10,"#,##0")&" ฿" -> 282 ราย / 22,165,200 ฿ | C17: ='5-Year Projection'!$D$6&" ราย / "&TEXT('5-Year Projection'!$D$11,"#,##0")&" ฿" -> 2810 ราย / 220,866,000 ฿ | D17: ='5-Year Projection'!$D$7&" ราย / "&TEXT('5-Year Projection'!$D$12,"#,##0")&" ฿" -> 16098 ราย / 1,265,302,800 ฿
A19: 3. มูลค่าที่ส่งหน้าการให้ลูกค้า (Product Value & Time Saved)
A20: รายการ | B20: Small | C20: Medium | D20: ใหญ่
A21: ชม.ที่ประหยัดได้/โครงการ (จากการถอดแบบ) | B21: ='Client — Small'!$B$13 -> 23.333333 | C21: ='Client — Medium'!$B$13 -> 116.66667 | D21: ='Client — Large'!$B$13 -> 311.11111
A22: มูลค่ารวม/ลูกค้า/ปี (เวลา+error+เศษเหล็ก) | B22: ='Client — Small'!$B$25 -> 60119.184 | C22: ='Client — Medium'!$B$25 -> 426107.06 | D22: ='Client — Large'!$B$25 -> 750964.12
A24: 4. Sustainability Impact (Year 3, tCO2e/ปี)
A25: รายการ | B25: Worst | C25: Base | D25: Best
A26: CO2 ที่ลดได้/ปี (ต้น) | B26: ='Sustainability Impact'!$B$32 -> 2672.1701 | C26: ='Sustainability Impact'!$C$32 -> 26626.943 | D26: ='Sustainability Impact'!$D$32 -> 152541.11
A27: ≈ เทียบเท่ากับต้นไม้ (ต้น) | B27: ='Sustainability Impact'!$B$33 -> 127246.2 | C27: ='Sustainability Impact'!$C$33 -> 1267949.7 | D27: ='Sustainability Impact'!$D$33 -> 7263862.6 | F27: 🟩 Metric 1 (เหล็ก/BBS) สอดคล้องเต็ม — Metric 2-3 (เลือกวัสดุ/Planner) 🟥 ยังเป็นสมมติฐานทีม — ดู Sustainability Impact
A29: 5. ข้อสำคัญสำหรับนักลงทุน (Key Flags)
A30: ⚠️ Small-segment ROI ≈ 1.0x — กำไรที่เหลือหลังหัก AI COGS อยู่เกือบ 100% แต่มูลค่าที่ลูกค้าได้เกือบเท่ากับราคาเพาะ — ดู Pricing Strategy
A31: ⚠️ SOM, Churn, Conversion, Willingness-to-Pay — ไม่มี survey/data จริงสำหรับตลาด Thai ConTech (BUILK precedent — ดู Assumptions!A92-95)
A32: ⚠️ Sustainability metrics 2-3 (เลือกวัสดุ/Planner) เป็นสมมติฐานทีม — ต้องมี pilot data ก่อนเสนอเป็น fact ชี้ขาด
A33: ⚠️ LTV:CAC = 78.6x — สูงเกินความปกติเนื่องจากสมมติฐาน lifetime 3ปี โดยไม่มี churn data — ต้องเก็บ data จริงมา revalidate
A34: ✅ UPDATE: เพื่อ self-serve leads สนเทียงชัดเจนเพื่อ Base Year1 > 1,000 ราย (=1,086) — แก้ Year4 growth เดีมด้วย (เคย nationwide-expansion แยกจาก GTM engine ทำให้ลูกค้าลดลง Year3→4 และต้นทุนติดลบ) — ตอนนี้ Year4-5 = Year3 × เติบโตติดกันด้วย GTM engine เดียวกัน — Net Margin ทุกปี~81-91% — 🔥 self-serve leads/conversion เป็นสมมติฐานทีมทั้นหมด ยังไม่มี marketing pilot จริงรองรับ

Sheet README
A1: Constistant — Financial Model
A3: โมเดลนี้สร้างจากสคริปต์ build_financial_model.py — ทุกช่องเป็นสูตร Excel จริง (ไม่ใช่ตัวเลขนิ่ง)
A4: ยกเว้นชีต Assumptions ที่เป็นค่าตั้งต้น แก้ที่นั่นที่เดียวแล้วทุกชีตจะคำนวณใหม่ทั้งหมด
A6: วิธีอ่านสี:
A7: 🟩 เขียว = มีที่มาอ้างอิงจริง จากงานวิจัยในโฟลเดอร์ STECON detail/Research/ (คอลัมน์ "ที่มา" บอกไฟล์+หัวข้อ)
A8: 🟨 เหลือง = สมมติฐาน — ไม่มีข้อมูลจริงรองรับ (เช่น ต้นทุนบริษัท, ราคาที่จะตั้ง, capture rate) ปรับได้อิสระ
A10: ลำดับชีต:
A11: 1. Assumptions — ค่าตั้งต้นทั้งหมด + dropdown เลือก Scenario (Worst/Base/Best) ที่เซลล์เดียว
A12: 2. Market — TopDown — ขนาดตลาดแบบ Top-Down (TAM→SAM→ผู้รับเหมา→กลุ่มพร้อมดิจิทัล→ลูกค้าที่จับได้)
A13: 3-5. Client — Small / Medium / Large — ต่อ 1 ลูกค้าแต่ละไซส์: เวลา/ต้นทุน error/เศษเหล็กที่ประหยัดได้ → ROI ให้ลูกค้า
A14: 6. Client — Summary — เทียบ 3 ไซส์ ถ่วงน้ำหนักเป็นรายได้เฉลี่ย/ลูกค้า
A15: 7-9. Business Model — Revenue / Cost / Profit — P&L บริษัท 3 ปี
... A28: อัปเดต 2026-09-02: แก้จำนวนผู้รับเหมาที่จดทะเป็น 80,000 ราย (จาก 108,000) และ SME% เป็น 99.93% (จาก 95%) เพิ่มตัวเลข waste ระดับอุตสาหกรรม (16.27% เหล็ก/8.92% คอนกรีต) และ BUILK PMF precedent ที่ Assumptions และ Competitors — ดู 2026-09-02-market-sizing-assumptions-summary.md เป็นแหล่งอ้างอิงหลัก

Sheet Assumptions
A1: Assumptions — ตัวเลขตั้งต้นของทั้งโมเดล
A2: แก้ค่าที่นี่ที่เดียว ทุกชีตอื่นดึงค่าจากตรงนี้ผ่านสูตรทั้งหมด ไม่มีตัวเลขฝังตรงในชีตอื่นเลย · 🟩 เขียว = มีที่มาอ้างอิงจริง (ดูคอลัมน์ "ที่มา") · 🟨 เหลือง = สมมติฐานที่ปรับได้ ยังไม่มีข้อมูลจริงรองรับ
A4: รายการ | B4: ค่า | C4: หน่วย | D4: ประเภท | E4: ที่มา / หมายเหตุ
A5: ตลาด (Top-Down Market) — จาก researchE.md
A6: มูลค่าตลาดก่อสร้างไทยรวม (TAM) — ต่ำ | B6: 1407000 | C6: ล้านบาท/ปี | D6: 🟩 อ้างอิงจริง | E6: Krungsri Research 2024 (2024-2027 forecast) — researchE.md §2
A7: มูลค่าตลาดก่อสร้างไทยรวม (TAM) — สูง | B7: 1410000 | C7: ล้านบาท/ปี | D7: 🟩 อ้างอิงจริง | E7: SCB EIC 2023 — researchE.md §2
A8: อัตราเติบโตตลาดรวม/ปี | B8: 0.02 | C8: %/ปี | D8: 🟩 อ้างอิงจริง | E8: Krungsri Research — คาดการณ์ 2025-2027 เติบโต 2.0-2.5%/ปี (ใช้ขอบล่างแบบอนุรักษนิยม) — researchE.md §2
A9: ตลาดเป้าหมายตรง (SAM) — ต่ำ | B9: 300000 | C9: ล้านบาท/ปี | D9: 🟩 อ้างอิงจริง | E9: RakMao 2024, บ้านแนวราบ+อาคารพาณิชย์เล็ก-กลาง ~25% ของ TAM — researchE.md §2
A10: ตลาดเป้าหมายตรง (SAM) — สูง | B10: 350000 | C10: ล้านบาท/ปี | D10: 🟩 อ้างอิงจริง | E10: RakMao 2024 — researchE.md §2
A11: ผู้รับเหมาจดทะเบียนนิติบุคคลทั่วประเทศ | B11: 80000 | C11: ราย | D11: 🟩 อ้างอิงจริง | E11: DBD (Dept. of Business Development) — ผู้รับเหมาจดทะเบียนนิติบุคคลทั่วประเทศ ~80,000 ราย — market-sizing-assumptions-summary.md §1 (แก้ไขจากตัวเลขเดิม 108,000 ซึ่งไม่ตรงกับแหล่งอ้างอิงล่าสุด)
A12: สัดส่วนที่เป็น SME (ไม่ใช่บริษัทใหญ่) | B12: 0.9993 | C12: % | D12: 🟩 อ้างอิงจริง | E12: 99.93% ของผู้ประกอบการทั้งหมด (≈79,945 ราย) เป็น SME — ส่วนที่เหลือ 55 บริษัทขนาดใหญ่ (0.07%) ถือ ~50% ของรายได้อุตสาหกรรมรวม — market-sizing-assumptions-summary.md §1 (แก้ไขจากตัวเลขเดิม 95%)
A13: สัดส่วนที่ "พร้อมปรับใช้เทคโนโลยีใหม่" จริง | B13: 0.2 | C13: % | D13: 🟩 อ้างอิงจริง | E13: TCA Magazine 2023 survey: 20% กำลังปรับใช้ / 60% รับรู้แต่ยังไม่ปรับ / 20% ไม่เปลี่ยนเลย — researchA.md §7
A14: สัดส่วนที่เข้าถึงได้จริงช่วงเริ่มต้น (โฟกัส กทม./ปริมณฑล/EEC ก่อน) | B14: 0.3 | C14: % | D14: 🟨 สมมติฐาน | E14: งานวิจัยยืนยันว่าอัตราเปิดรับดิจิทัลในเขต กทม./ปริมณฑล/EEC สูงกว่าภูมิภาคอื่นอย่างมีนัยสำคัญ แต่ไม่มีตัวเลขสัดส่วนที่แน่นอน (Data Gap #2) — researchE.md §7. 30% เป็นสมมติฐานทีมจากสัดส่วนกิจกรรมก่อสร้างที่กระจุกตัวในเขตนี้ ใช้เป็นขอบเขต GTM ปีแรกๆ ที่ทีมเล็กเข้าถึงได้จริง แทนที่จะอ้างว่าเข้าถึงทั้งประเทศพร้อมกัน
A15: Scenario ที่เลือกอยู่ (สลับตรงนี้ ทั้งชีตจะขยับตาม)
A16: ❌ เลิกเลิก (retired) — กลไก capture-rate แบบ flat เดีม (0.5%/1.5%/4%) เลิกใช้แล้ว — จำนวนลูกค้าจริงคำนวณจาก GTM—Bottom-Up (B119-126) โดยตรง — เห็นทุก Scenario เป็นชีตต่อกันแล้ว (ไม่ต้อง dropdown) | B16: Best | D16: 🟨 สมมติฐาน | E16: ⚪ เหลือไว้เป็น label เฉยๆ — ไม่ขับเคลื่อนสูตรไหนแล้ว — ทุกชีต (Cost Structure, 5-Year Projection, Dashboard) แสดง Worst/Base/Best เคียงกันเสมอ ไม่ต้องสลับ
A24: ประสิทธิภาพที่ใช้ร่วมกันทุกไซส์ลูกค้า — จาก researchA.md
A25: Constistant ทำงานเร็วกว่าถอดแบบมือกี่เท่า | B25: 4.5 | C25: เท่า | D25: 🟩 อ้างอิงจริง | E25: 1-2 ชม./หมวดด้วยซอฟต์แวร์ vs. 6-8 ชม./หมวดด้วยมือ = เร็วกว่า 4-5 เท่า (ใช้ค่ากลาง) — researchA.md §2
A26: ชั่วโมงถอดแบบมือ ต่อ ตร.ม. (อ้างอิงบ้าน 300 ตร.ม. ใช้ 30 ชม.) | B26: 0.1 | C26: ชม./ตร.ม. | D26: 🟩 อ้างอิงจริง | E26: อนุพันธ์จาก 20-40 ชม. (ค่ากลาง 30 ชม.) ÷ พื้นที่กลาง 300 ตร.ม. (200-400 ตร.ม.) — researchA.md §2
A27: มูลค่าเวลาวิศวกร (บาท/ชม.) | B27: 175 | C27: บาท/ชม. | D27: 🟨 สมมติฐาน | E27: ประมาณจากเงินเดือนวิศวกร Junior/Mid ~30,000 บาท/เดือน ÷ 173 ชม.ทำงาน/เดือน — สมมติฐาน (ไม่มีตัวเลขนี้ตรงๆ ในงานวิจัย)
A28: ความเสี่ยง error จากการถอดแบบมือ — จาก researchA.md
A29: โอกาสเกิด error รุนแรงต่อโครงการ | B29: 0.075 | C29: % | D29: 🟩 อ้างอิงจริง | E29: ค่ากลางของอัตรา fatigue error 5-10% บนแบบชุดใหญ่ — researchA.md §3
A30: ความเสียหายเมื่อเกิด error (% ของงบโครงการ) | B30: 0.075 | C30: % ของงบ | D30: 🟩 อ้างอิงจริง | E30: อนุพันธ์จาก 150,000-1,000,000 บาท ความเสียหาย บนงบ 3-10 ล้านบาท (150k/3M=5% ถึง 1M/10M=10%, ค่ากลาง 7.5%) — researchA.md §5
A31: Constistant ลดความเสี่ยงนี้ได้กี่ % | B31: 0.9 | C31: % | D31: 🟨 สมมติฐาน | E31: จากความแม่นยำดิจิทัล 95-99% เทียบมือ 75-90% (researchA.md §3) — แปลงเป็น "ลดความเสี่ยงลง 90%" เป็นสมมติฐานประมาณการ
A32: เหล็กเสริมและเศษเหล็ก — จาก researchA.md / researchC.md / ข้อมูลจริงของแอป
A33: ราคาเหล็กเฉลี่ย (บาท/กก., ไม่รวม VAT) | B33: 21.5 | C33: บาท/กก. | D33: 🟩 อ้างอิงจริง | E33: เฉลี่ย 18.45-25.34 บาท/กก. (~21,500 บาท/ตัน) — researchC.md §1
A34: น้ำหนักเหล็กโดยประมาณ ต่อ ตร.ม. | B34: 73.7 | C34: กก./ตร.ม. | D34: 🟩 อ้างอิงจริง | E34: จากข้อมูลจริงของแอป Constistant เอง — โปรเจกต์เดโม 2 (บ้าน 400 ตร.ม. ชั้นเดียว) เหล็กรวม 29,486.95 กก. ÷ 400 ตร.ม. (CLAUDE.md work log, 2026-08-31)
A35: เศษเหล็กจากการตัดด้วยมือ (% ของน้ำหนักเหล็ก) | B35: 0.065 | C35: % | D35: 🟩 อ้างอิงจริง | E35: ค่ากลางของช่วง 5-8% (สูงสุด 11.5% ในอาคารต้านแผ่นดินไหว) — researchA.md §4
A36: เศษเหล็กหลัง optimize — ทฤษฎีจากงานวิจัย (% ของน้ำหนักเหล็ก) | B36: 0.03 | C36: % | D36: 🟩 อ้างอิงจริง | E36: ค่ากลางของช่วง 0.4-5.31% ขึ้นกับวิธี (GA/ILP/Special-length) — researchA.md §4, researchC.md §2
A37: เศษเหล็กที่ลดได้จริง — วัดจากระบบ Constistant เอง (ลดสัมพัทธ์เฉลี่ย) | B37: 0.1 | C37: % ลดสัมพัทธ์ | D37: 🟩 อ้างอิงจริง | E37: วัดจริงด้วย optimizeCuttingStock() บนโปรเจกต์เดโม 2 โครงการของแอปเอง: โปรเจกต์ 1 ลดจาก 4.67%→3.73% (ลด 20.1%), โปรเจกต์ 2 ไม่ลดเลย (0%, เพราะเหล็กยาวเกินครึ่งเหล็กหน้างาน จับคู่เศษไม่ได้) — เฉลี่ย ~10% เป็นค่ากลางที่อนุรักษนิยมกว่า ตัวเลขทฤษฎีด้านบนมาก และเป็นตัวเลขที่ "วัดได้จริง" ไม่ใช่ทฤษฎี
A38: นิยามไซส์ลูกค้า — ขนาดงาน/ปี
A39: Small — พื้นที่ต่อโครงการ | B39: 300 | C39: ตร.ม. | D39: 🟩 อ้างอิงจริง | E39: ค่ากลางบ้าน 2 ชั้น 200-400 ตร.ม. — ตรงกับ scope ของ researchA.md ทั้งฉบับ
A40: Small — งบประมาณต่อโครงการ | B40: 6500000 | C40: บาท | D40: 🟩 อ้างอิงจริง | E40: ค่ากลางงบ 3-10 ล้านบาท ที่ researchA.md §5 ใช้พูดถึงผลกระทบทางการเงิน
A41: Small — จำนวนโครงการ/ปี ต่อ 1 ลูกค้า — ต่ำ | B41: 1 | C41: โครงการ/ปี | D41: 🟨 สมมติฐาน | E41: ผู้รับเหมารายเล็ก/เจ้าของบ้านมักทำ 1-2 โครงการบ้านเดี่ยว/ปี — สมมติฐาน
A42: Small — จำนวนโครงการ/ปี ต่อ 1 ลูกค้า — สูง | B42: 2 | C42: โครงการ/ปี | D42: 🟨 สมมติฐาน | E42: สมมติฐาน
A43: → Small — จำนวนโครงการ/ปี (ค่ากลาง, สูตร) | B43: =AVERAGE(B41,B42) -> 1.5 | C43: โครงการ/ปี | D43: ⚪ สูตร
A44: Medium — พื้นที่ต่อโครงการ | B44: 1500 | C44: ตร.ม. | D44: 🟨 สมมติฐาน | E44: อาคารพาณิชย์/ที่พักอาศัยหลายหน่วยขนาดเล็ก-กลาง ตาม scope ของ SAM (researchE.md §2) — ไม่มีตัวเลข sqm ชัดเจนในงานวิจัย จึงเป็นสมมติฐาน
A45: Medium — งบประมาณต่อโครงการ | B45: 35000000 | C45: บาท | D45: 🟨 สมมติฐาน | E45: สเกลตามสัดส่วนพื้นที่จาก Small (~5 เท่า) — สมมติฐาน
A46: Medium — จำนวนโครงการ/ปี ต่อ 1 ลูกค้า — ต่ำ | B46: 1 | C46: โครงการ/ปี | D46: 🟨 สมมติฐาน | E46: สมมติฐาน
A47: Medium — จำนวนโครงการ/ปี ต่อ 1 ลูกค้า — สูง | B47: 3 | C47: โครงการ/ปี | D47: 🟨 สมมติฐาน | E47: สมมติฐาน
A48: → Medium — จำนวนโครงการ/ปี (ค่ากลาง, สูตร) | B48: =AVERAGE(B46,B47) -> 2 | C48: โครงการ/ปี | D48: ⚪ สูตร
...

Sheet GTM — Bottom-Up
A1: GTM — Bottom-Up Sales Funnel (แหล่งจริงของ Worst/Base/Best)
A2: เหล้าเดียวกัน: จำนวน sales rep × leads/rep/เดือน × close rate = ลูกค้าใหม่/ปี — หักลูกค้าเก่าที่ churn ออก → สะสมสุดเป็นลูกค้าสะสมที่ป้อนเข้า Market—TopDown
A4: Worst Case
A5: รายการ | B5: ปี 1 | C5: ปี 2 | D5: ปี 3 | E5: สูตร
A6: Sales reps | B6: =Assumptions!$B$121 -> 1 | C6: =Assumptions!$B$122 -> 1 | D6: =Assumptions!$B$123 -> 1 | E6: Assumptions!B121:B123
A7: Leads/rep/เดือน | B7: =Assumptions!$B$124 -> 5 | C7: =Assumptions!$B$124 -> 5 | D7: =Assumptions!$B$124 -> 5
A8: Close rate | B8: =Assumptions!$B$125 -> 0.03 | C8: =Assumptions!$B$125 -> 0.03 | D8: =Assumptions!$B$125 -> 0.03
A9: → ลูกค้าใหม่/ปี (Channel 1: sales rep + Channel 2: self-serve) | B9: =B6*B7*12*B8+$B$38 -> 121.8 | C9: =C6*C7*12*C8+$B$38 -> 121.8 | D9: =D6*D7*12*D8+$B$38 -> 121.8
A10: คงเหลือจากปีก่อน หลัง churn | B10: =0 -> 0 | C10: =B12*(1-Assumptions!$B$126) -> 91.5 | D10: =C12*(1-Assumptions!$B$126) -> 159.75
A11: Churn rate/ปี | B11: =Assumptions!$B$126 -> 0.25 | C11: =Assumptions!$B$126 -> 0.25 | D11: =Assumptions!$B$126 -> 0.25
A12: → ลูกค้าสะสม (คงเหลือ + ใหม่) | B12: =ROUND(B10+B9,0) -> 122 | C12: =ROUND(C10+C9,0) -> 213 | D12: =ROUND(D10+D9,0) -> 282
A14: Base Case
A15: รายการ | B15: ปี 1 | C15: ปี 2 | D15: ปี 3
A16: Sales reps | B16: =Assumptions!$C$121 -> 1 | C16: =Assumptions!$C$122 -> 2 | D16: =Assumptions!$C$123 -> 3
A17: Leads/rep/เดือน | B17: =Assumptions!$C$124 -> 8 | C17: =Assumptions!$C$124 -> 8 | D17: =Assumptions!$C$124 -> 8
A18: Close rate | B18: =Assumptions!$C$125 -> 0.06 | C18: =Assumptions!$C$125 -> 0.06 | D18: =Assumptions!$C$125 -> 0.06
A19: → ลูกค้าใหม่/ปี (Channel 1: sales rep + Channel 2: self-serve) | B19: =B16*B17*12*B18+$C$38 -> 1085.76 | C19: =C16*C17*12*C18+$C$38 -> 1091.52 | D19: =D16*D17*12*D18+$C$38 -> 1097.28
A20: คงเหลือจากปีก่อน หลัง churn | B20: =0 -> 0 | C20: =B22*(1-Assumptions!$C$126) -> 923.1 | D20: =C22*(1-Assumptions!$C$126) -> 1712.75
A21: Churn rate/ปี | B21: =Assumptions!$C$126 -> 0.15 | C21: =Assumptions!$C$126 -> 0.15 | D21: =Assumptions!$C$126 -> 0.15
A22: → ลูกค้าสะสม | B22: =ROUND(B20+B19,0) -> 1086 | C22: =ROUND(C20+C19,0) -> 2015 | D22: =ROUND(D20+D19,0) -> 2810
A24: Best Case
A25: รายการ | B25: ปี 1 | C25: ปี 2 | D25: ปี 3
A26: Sales reps | B26: =Assumptions!$D$121 -> 2 | C26: =Assumptions!$D$122 -> 4 | D26: =Assumptions!$D$123 -> 6
A27: Leads/rep/เดือน | B27: =Assumptions!$D$124 -> 12 | C27: =Assumptions!$D$124 -> 12 | D27: =Assumptions!$D$124 -> 12
A28: Close rate | B28: =Assumptions!$D$125 -> 0.1 | C28: =Assumptions!$D$125 -> 0.1 | D28: =Assumptions!$D$125 -> 0.1
A29: → ลูกค้าใหม่/ปี (Channel 1: sales rep + Channel 2: self-serve) | B29: =B26*B27*12*B28+$D$38 -> 5788.8 | C29: =C26*C27*12*C28+$D$38 -> 5817.6 | D29: =D26*D27*12*D28+$D$38 -> 5846.4
A30: คงเหลือจากปีก่อน หลัง churn | B30: =0 -> 0 | C30: =B32*(1-Assumptions!$D$126) -> 5325.88 | D30: =C32*(1-Assumptions!$D$126) -> 10251.56
A31: Churn rate/ปี | B31: =Assumptions!$D$126 -> 0.08 | C31: =Assumptions!$D$126 -> 0.08 | D31: =Assumptions!$D$126 -> 0.08
A32: → ลูกค้าสะสม | B32: =ROUND(B30+B29,0) -> 5789 | C32: =ROUND(C30+C29,0) -> 11143 | D32: =ROUND(D30+D29,0) -> 16098
A34: Channel 2 (Self-Serve) — เพิ่มเหนือ Channel 1 — เหชนเดือนคือสเกตอิสระคียกำงกับ Small เดียว
A35: รายการ | B35: Worst | C35: Base | D35: Best
A36: Leads/เดือน (marketing) | B36: =Assumptions!$B$140 -> 1000 | C36: =Assumptions!$C$140 -> 3000 | D36: =Assumptions!$D$140 -> 8000
A37: Signup → paid conversion | B37: =Assumptions!$B$141 -> 0.01 | C37: =Assumptions!$C$141 -> 0.03 | D37: =Assumptions!$D$141 -> 0.06
A38: → ลูกค้าใหม่/ปี จาก self-serve (leads×12×conversion) | B38: =B36*12*B37 -> 120 | C38: =C36*12*C37 -> 1080 | D38: =D36*12*D37 -> 5760

Sheet Market — TopDown
A1: Market — Top-Down Sizing
A2: TAM → SAM → ผู้รับเหมาที่เข้าถึงได้ → กลุ่มพร้อมดิจิทัล → ลูกค้าที่จับได้ (SOM) ต่อปี ต่อ Scenario
A4: Funnel
A5: มูลค่าตลาดรวม (TAM, ค่ากลาง) | B5: =AVERAGE(Assumptions!$B$6,Assumptions!$B$7) -> 1408500 | C5: ล้านบาท/ปี
A6: ตลาดเป้าหมายตรง (SAM, ค่ากลาง) | B6: =AVERAGE(Assumptions!$B$9,Assumptions!$B$10) -> 325000 | C6: ล้านบาท/ปี
A7: ผู้รับเหมา SME ที่เข้าถึงได้ (80,000 × %SME) | B7: =Assumptions!$B$11*Assumptions!$B$12 -> 79944 | C7: ราย
A8: กลุ่มพร้อมปรับใช้ดิจิทัลจริง (× 20%) | B8: =B7*Assumptions!$B$13 -> 15988.8 | C8: ราย
A9: → กลุ่มที่เข้าถึงได้จริงช่วงเริ่มต้น (โฟกัส กทม./ปริมณฑล/EEC ก่อน) | B9: =B8*Assumptions!$B$14 -> 4796.64 | C9: ราย
A11: ลูกค้าที่จับได้ (SOM) — จาก GTM — Bottom-Up (เหล้าจำนวน sales rep × leads × close rate − churn) เปลี่ยนจาก flat %capture เดีม
A12: ปี | B12: Worst (ราย) | C12: Base (ราย) | D12: Best (ราย)
A13: ปีที่ 1 | B13: ='GTM — Bottom-Up'!$B$12 -> 122 | C13: ='GTM — Bottom-Up'!$B$22 -> 1086 | D13: ='GTM — Bottom-Up'!$B$32 -> 5789
A14: ปีที่ 2 | B14: ='GTM — Bottom-Up'!$C$12 -> 213 | C14: ='GTM — Bottom-Up'!$C$22 -> 2015 | D14: ='GTM — Bottom-Up'!$C$32 -> 11143
A15: ปีที่ 3 | B15: ='GTM — Bottom-Up'!$D$12 -> 282 | C15: ='GTM — Bottom-Up'!$D$22 -> 2810 | D15: ='GTM — Bottom-Up'!$D$32 -> 16098
A23: → กลุ่มที่เข้าถึงได้จริงปีที่ 4 (ขยายทั่วประเทศ) | B23: =B8*Assumptions!$B$74 -> 15988.8 | C23: ราย
A25: ลูกค้าสะสมปีที่ 4 = ปี 3 × อัตราเติบโต (Assumptions!B117) — ต่อเนื่อง GTM engine เดียวกัน ไม่สลับไปใช้สมมติฐานขยายที่ตัดกันแล้ว | B25: Worst (ราย) | C25: Base (ราย) | D25: Best (ราย)
A26: ปีที่ 4 | B26: =B15*Assumptions!$B$117 -> 564 | C26: =C15*Assumptions!$B$117 -> 5620 | D26: =D15*Assumptions!$B$117 -> 32196
A31: เทียบรายได้ปีที่ 4/5/6 (Best-case) — เติบโต 2 เท่า/ปี: 300M → 600M → 1,200M
A32: ปี | B32: ลูกค้าสะสม Best (ราย)
A33: ปีที่ 4 | B33: =ROUND($B$23*Assumptions!$B$77,0) -> 3181
A34: ปีที่ 5 | B34: =ROUND($B$23*Assumptions!$B$82,0) -> 6361
A35: ปีที่ 6 | B35: =ROUND($B$23*Assumptions!$B$83,0) -> 12723

Sheet Client — Small
A1: Client — Small (บ้านเดี่ยว/รายย่อย)
A2: ขนาดงาน · เวลาที่ใช้แบบมือ vs. Constistant · มูลค่าที่ประหยัดได้ · ราคาที่เราคิด · ROI ให้ลูกค้า — ทุกช่องเป็นสูตรอ้างอิง Assumptions
A4: รายการ | B4: ค่า | C4: หน่วย | D4: สูตร/ที่มา
A5: ขนาดงาน
A6: พื้นที่ก่อสร้าง (เทียบเท่า) | B6: =Assumptions!$B$39 -> 300 | C6: ตร.ม.
A7: งบประมาณ/มูลค่างานต่อโครงการ | B7: =Assumptions!$B$40 -> 6500000 | C7: บาท
A8: จำนวนโครงการ/งาน ต่อปี ต่อ 1 ลูกค้า (ค่ากลางของช่วง) | B8: =Assumptions!$B$43 -> 1.5 | C8: โครงการ/ปี
A9: น้ำหนักเหล็กโดยประมาณ/โครงการ | B9: =B6*Assumptions!$B$34 -> 22110 | C9: กก. | D9: พื้นที่ × กก./ตร.ม. (Assumptions)
A10: เวลาที่ใช้: มือ vs. Constistant
A11: ชั่วโมงถอดแบบด้วยมือ/โครงการ | B11: =B6*Assumptions!$B$26 -> 30 | C11: ชม.
A12: ชั่วโมงด้วย Constistant/โครงการ | B12: =B11/Assumptions!$B$25 -> 6.6666667 | C12: ชม.
A13: ชั่วโมงที่ประหยัดได้/โครงการ | B13: =B11-B12 -> 23.333333 | C13: ชม.
A14: มูลค่าเวลาที่ประหยัดได้/โครงการ | B14: =B13*Assumptions!$B$27 -> 4083.3333 | C14: บาท
A15: ความเสี่ยง error ที่หลีกเลี่ยงได้
A16: มูลค่าความเสียหายที่หลีกเลี่ยงได้/โครงการ | B16: =B7*Assumptions!$B$29*Assumptions!$B$30*Assumptions!$B$31 -> 32906.25 | C16: บาท | D16: งบ × โอกาสเกิด × ความเสียหาย% × Constistant ลดความเสี่ยงได้กี่%
A17: เศษเหล็กที่ประหยัดได้
A18: เศษเหล็กแบบมือ | B18: =B9*Assumptions!$B$35 -> 1437.15 | C18: กก.
A19: เศษเหล็กหลัง optimize — ทฤษฎีงานวิจัย | B19: =B9*Assumptions!$B$36 -> 663.3 | C19: กก.
A20: เศษเหล็กหลัง optimize — วัดจากระบบจริง | B20: =B18*(1-Assumptions!$B$37) -> 1293.435 | C20: กก.
A21: มูลค่าที่ประหยัดได้ — ทฤษฎีงานวิจัย | B21: =(B18-B19)*Assumptions!$B$33 -> 16637.775 | C21: บาท
A22: มูลค่าที่ประหยัดได้ — วัดจากระบบจริง (ใช้ค่านี้เป็นหลัก อนุรักษนิยมกว่า) | B22: =(B18-B20)*Assumptions!$B$33 -> 3089.8725 | C22: บาท
A23: รวมมูลค่าที่ลูกค้าได้รับ
A24: รวมมูลค่าที่ได้รับ/โครงการ (ใช้เศษเหล็ก "วัดจริง") | B24: =B14+B16+B22 -> 40079.456 | C24: บาท
A25: รวมมูลค่าที่ได้รับ/ปี (ต่อ 1 ลูกค้า) | B25: =B24*B8 -> 60119.184 | C25: บาท
A26: ราคาที่ Constistant เก็บ และ ROI ให้ลูกค้า
A27: ราคา SaaS ต่อเดือน | B27: =Assumptions!$B$55 -> 5000 | C27: บาท/เดือน
A28: → รายได้ที่เราได้รับ/ปี (ต่อ 1 ลูกค้า) | B28: =B27*12 -> 60000 | C28: บาท
A29: ROI ให้ลูกค้า (มูลค่าที่ได้รับ ÷ ราคาที่จ่าย) | B29: =B25/B28 -> 1.0019864 | C29: เท่า

Sheet Client — Medium
A1: Client — Medium (อาคารพาณิชย์/ที่พักหลายหน่วยขนาดกลาง)
A2: ขนาดงาน · เวลาที่ใช้แบบมือ vs. Constistant · มูลค่าที่ประหยัดได้ · ราคาที่เราคิด · ROI ให้ลูกค้า — ทุกช่องเป็นสูตรอ้างอิง Assumptions
A4: รายการ | B4: ค่า | C4: หน่วย | D4: สูตร/ที่มา
A5: ขนาดงาน
A6: พื้นที่ก่อสร้าง (เทียบเท่า) | B6: =Assumptions!$B$44 -> 1500 | C6: ตร.ม.
A7: งบประมาณ/มูลค่างานต่อโครงการ | B7: =Assumptions!$B$45 -> 35000000 | C7: บาท
A8: จำนวนโครงการ/งาน ต่อปี ต่อ 1 ลูกค้า (ค่ากลางของช่วง) | B8: =Assumptions!$B$48 -> 2 | C8: โครงการ/ปี
A9: น้ำหนักเหล็กโดยประมาณ/โครงการ | B9: =B6*Assumptions!$B$34 -> 110550 | C9: กก. | D9: พื้นที่ × กก./ตร.ม. (Assumptions)
A10: เวลาที่ใช้: มือ vs. Constistant
A11: ชั่วโมงถอดแบบด้วยมือ/โครงการ | B11: =B6*Assumptions!$B$26 -> 150 | C11: ชม.
A12: ชั่วโมงด้วย Constistant/โครงการ | B12: =B11/Assumptions!$B$25 -> 33.333333 | C12: ชม.
A13: ชั่วโมงที่ประหยัดได้/โครงการ | B13: =B11-B12 -> 116.66667 | C13: ชม.
A14: มูลค่าเวลาที่ประหยัดได้/โครงการ | B14: =B13*Assumptions!$B$27 -> 20416.667 | C14: บาท
A15: ความเสี่ยง error ที่หลีกเลี่ยงได้
A16: มูลค่าความเสียหายที่หลีกเลี่ยงได้/โครงการ | B16: =B7*Assumptions!$B$29*Assumptions!$B$30*Assumptions!$B$31 -> 177187.5 | C16: บาท | D16: งบ × โอกาสเกิด × ความเสียหาย% × Constistant ลดความเสี่ยงได้กี่%
A17: เศษเหล็กที่ประหยัดได้
A18: เศษเหล็กแบบมือ | B18: =B9*Assumptions!$B$35 -> 7185.75 | C18: กก.
A19: เศษเหล็กหลัง optimize — ทฤษฎีงานวิจัย | B19: =B9*Assumptions!$B$36 -> 3316.5 | C19: กก.
A20: เศษเหล็กหลัง optimize — วัดจากระบบจริง | B20: =B18*(1-Assumptions!$B$37) -> 6467.175 | C20: กก.
A21: มูลค่าที่ประหยัดได้ — ทฤษฎีงานวิจัย | B21: =(B18-B19)*Assumptions!$B$33 -> 83188.875 | C21: บาท
A22: มูลค่าที่ประหยัดได้ — วัดจากระบบจริง (ใช้ค่านี้เป็นหลัก อนุรักษนิยมกว่า) | B22: =(B18-B20)*Assumptions!$B$33 -> 15449.362 | C22: บาท
A23: รวมมูลค่าที่ลูกค้าได้รับ
A24: รวมมูลค่าที่ได้รับ/โครงการ (ใช้เศษเหล็ก "วัดจริง") | B24: =B14+B16+B22 -> 213053.53 | C24: บาท
A25: รวมมูลค่าที่ได้รับ/ปี (ต่อ 1 ลูกค้า) | B25: =B24*B8 -> 426107.06 | C25: บาท
A26: ราคาที่ Constistant เก็บ และ ROI ให้ลูกค้า
A27: ราคา SaaS ต่อเดือน | B27: =Assumptions!$B$56 -> 7000 | C27: บาท
A28: → รายได้ที่เราได้รับ/ปี (ต่อ 1 ลูกค้า) | B28: =B27*12 -> 84000 | C28: บาท
A29: ROI ให้ลูกค้า (มูลค่าที่ได้รับ ÷ ราคาที่จ่าย) | B29: =B25/B28 -> 5.0727031 | C29: เท่า

Sheet Client — Large
A1: Client — ใหญ่ (อาคารพาณิชย์/คอนโดขนาดใหญ่)
A2: ขนาดงาน · เวลาที่ใช้แบบมือ vs. Constistant · มูลค่าที่ประหยัดได้ · ราคาที่เราคิด · ROI ให้ลูกค้า — ทุกช่องเป็นสูตรอ้างอิง Assumptions
A4: รายการ | B4: ค่า | C4: หน่วย | D4: สูตร/ที่มา
A5: ขนาดงาน
A6: พื้นที่ก่อสร้าง (เทียบเท่า) | B6: =Assumptions!$B$49 -> 4000 | C6: ตร.ม.
A7: งบประมาณ/มูลค่างานต่อโครงการ | B7: =Assumptions!$B$50 -> 80000000 | C7: บาท
A8: จำนวนโครงการ/งาน ต่อปี ต่อ 1 ลูกค้า (ค่ากลางของช่วง) | B8: =Assumptions!$B$53 -> 1.5 | C8: โครงการ/ปี
A9: น้ำหนักเหล็กโดยประมาณ/โครงการ | B9: =B6*Assumptions!$B$34 -> 294800 | C9: กก. | D9: พื้นที่ × กก./ตร.ม. (Assumptions)
A10: เวลาที่ใช้: มือ vs. Constistant
A11: ชั่วโมงถอดแบบด้วยมือ/โครงการ | B11: =B6*Assumptions!$B$26 -> 400 | C11: ชม.
A12: ชั่วโมงด้วย Constistant/โครงการ | B12: =B11/Assumptions!$B$25 -> 88.888889 | C12: ชม.
A13: ชั่วโมงที่ประหยัดได้/โครงการ | B13: =B11-B12 -> 311.11111 | C13: ชม.
A14: มูลค่าเวลาที่ประหยัดได้/โครงการ | B14: =B13*Assumptions!$B$27 -> 54444.444 | C14: บาท
A15: ความเสี่ยง error ที่หลีกเลี่ยงได้
A16: มูลค่าความเสียหายที่หลีกเลี่ยงได้/โครงการ | B16: =B7*Assumptions!$B$29*Assumptions!$B$30*Assumptions!$B$31 -> 405000 | C16: บาท | D16: งบ × โอกาสเกิด × ความเสียหาย% × Constistant ลดความเสี่ยงได้กี่%
A17: เศษเหล็กที่ประหยัดได้
A18: เศษเหล็กแบบมือ | B18: =B9*Assumptions!$B$35 -> 19162 | C18: กก.
A19: เศษเหล็กหลัง optimize — ทฤษฎีงานวิจัย | B19: =B9*Assumptions!$B$36 -> 8844 | C19: กก.
A20: เศษเหล็กหลัง optimize — วัดจากระบบจริง | B20: =B18*(1-Assumptions!$B$37) -> 17245.8 | C20: กก.
A21: มูลค่าที่ประหยัดได้ — ทฤษฎีงานวิจัย | B21: =(B18-B19)*Assumptions!$B$33 -> 221837 | C21: บาท
A22: มูลค่าที่ประหยัดได้ — วัดจากระบบจริง (ใช้ค่านี้เป็นหลัก อนุรักษนิยมกว่า) | B22: =(B18-B20)*Assumptions!$B$33 -> 41198.3 | C22: บาท
A23: รวมมูลค่าที่ลูกค้าได้รับ
A24: รวมมูลค่าที่ได้รับ/โครงการ (ใช้เศษเหล็ก "วัดจริง") | B24: =B14+B16+B22 -> 500642.74 | C24: บาท
A25: รวมมูลค่าที่ได้รับ/ปี (ต่อ 1 ลูกค้า) | B25: =B24*B8 -> 750964.12 | C25: บาท
A26: ราคาที่ Constistant เก็บ และ ROI ให้ลูกค้า
A27: ราคา SaaS ต่อเดือน (องค์กร) | B27: =Assumptions!$B$57 -> 12000 | C27: บาท/เดือน
A28: → รายได้ที่เราได้รับ/ปี (ต่อ 1 ลูกค้า) | B28: =B27*12 -> 144000 | C28: บาท
A29: ROI ให้ลูกค้า (มูลค่าที่ได้รับ ÷ ราคาที่จ่าย) | B29: =B25/B28 -> 5.2150286 | C29: เท่า

Sheet Client — Summary
A1: Client — Summary
A2: เทียบ 3 ไซส์ลูกค้าเคียงกัน แล้วถ่วงน้ำหนักตามสัดส่วนลูกค้า → รายได้เฉลี่ย/ลูกค้า/ปี ที่ป้อนเข้า Business Model
A4: รายการ | B4: Small | C4: Medium | D4: ใหญ่ | E4: ถ่วงน้ำหนัก (Blended)
A5: พื้นที่/ขนาดงาน (ตร.ม. เทียบเท่า) | B5: ='Client — Small'!B6 -> 300 | C5: ='Client — Medium'!B6 -> 1500 | D5: ='Client — Large'!B6 -> 4000 | E5: =B5*Assumptions!$B$59+C5*Assumptions!$B$60+D5*Assumptions!$B$61 -> 1155
A6: งบประมาณต่อโครงการ | B6: ='Client — Small'!B7 -> 6500000 | C6: ='Client — Medium'!B7 -> 35000000 | D6: ='Client — Large'!B7 -> 80000000 | E6: =B6*Assumptions!$B$59+C6*Assumptions!$B$60+D6*Assumptions!$B$61 -> 24650000
A7: มูลค่าที่ลูกค้าได้รับ/ปี | B7: ='Client — Small'!B25 -> 60119.184 | C7: ='Client — Medium'!B25 -> 426107.06 | D7: ='Client — Large'!B25 -> 750964.12 | E7: =B7*Assumptions!$B$59+C7*Assumptions!$B$60+D7*Assumptions!$B$61 -> 255242.89
A8: รายได้ที่เราได้รับ/ปี ต่อ 1 ลูกค้า | B8: ='Client — Small'!B28 -> 60000 | C8: ='Client — Medium'!B28 -> 84000 | D8: ='Client — Large'!B28 -> 144000 | E8: =B8*Assumptions!$B$59+C8*Assumptions!$B$60+D8*Assumptions!$B$61 -> 78600
A9: ROI ให้ลูกค้า | B9: ='Client — Small'!B29 -> 1.0019864 | C9: ='Client — Medium'!B29 -> 5.0727031 | D9: ='Client — Large'!B29 -> 5.2150286 | E9: =B9*Assumptions!$B$59+C9*Assumptions!$B$60+D9*Assumptions!$B$61 -> 2.6516219
A11: ราคาจริงที่เก็บ — ทั้ง 3 ไซส์เป็น SaaS จ่ายรายเดือนเหมือนกัน
A12: ราคา (บาท/เดือน) | B12: ='Client — Small'!B27 -> 5000 | C12: ='Client — Medium'!B27 -> 7000 | D12: ='Client — Large'!B27 -> 12000 | E12: =B12*Assumptions!$B$59+C12*Assumptions!$B$60+D12*Assumptions!$B$61 -> 6550
A14: สัดส่วนลูกค้า (จาก Assumptions)
A15: สัดส่วนลูกค้าแต่ละไซส์ | B15: =Assumptions!$B$59 -> 0.6 | C15: =Assumptions!$B$60 -> 0.25 | D15: =Assumptions!$B$61 -> 0.15
A17: ปีที่ 4 — ARPU เฉลี่ย/ลูกค้า/ปี (รวม upsell) | E17: =E8*(1+Assumptions!$B$78) -> 94320
A19: กำไรที่เพิ่มขึ้น / cost ที่ลดลงของลูกค้า — แยกตามแหล่งที่มา (บาท/ปี ต่อ 1 ลูกค้า) — เนื่องจากงบ/รายได้ของลูกค้าไม่เปลี่ยน cost ที่ลดลงจึงช่วยกำไรโดยตรง
A20: แหล่งที่มา | B20: Small | C20: Medium | D20: ใหญ่ | E20: ถ่วงน้ำหนัก (Blended)
A21: 1) จากเวลาที่ประหยัดได้ (ลด cost แรงงานถอดแบบ) | B21: ='Client — Small'!B14*'Client — Small'!B8 -> 6125 | C21: ='Client — Medium'!B14*'Client — Medium'!B8 -> 40833.333 | D21: ='Client — Large'!B14*'Client — Large'!B8 -> 81666.667 | E21: =B21*Assumptions!$B$59+C21*Assumptions!$B$60+D21*Assumptions!$B$61 -> 26133.333
A22: 2) จากความเสี่ยง error ที่หลีกเลี่ยงได้ (ลด cost ความเสียหาย) | B22: ='Client — Small'!B16*'Client — Small'!B8 -> 49359.375 | C22: ='Client — Medium'!B16*'Client — Medium'!B8 -> 354375 | D22: ='Client — Large'!B16*'Client — Large'!B8 -> 607500 | E22: =B22*Assumptions!$B$59+C22*Assumptions!$B$60+D22*Assumptions!$B$61 -> 209334.38
A23: 3) จากเศษเหล็กที่ประหยัดได้ (ลด cost วัสดุ, เลขวัดจริง) | B23: ='Client — Small'!B22*'Client — Small'!B8 -> 4634.8087 | C23: ='Client — Medium'!B22*'Client — Medium'!B8 -> 30898.725 | D23: ='Client — Large'!B22*'Client — Large'!B8 -> 61797.45 | E23: =B23*Assumptions!$B$59+C23*Assumptions!$B$60+D23*Assumptions!$B$61 -> 19775.184
A24: รวม = กำไรที่เพิ่มขึ้นของลูกค้า/ปี (ผลรวหจาก cost ที่ลด) | B24: =B21+B22+B23 -> 60119.184 | C24: =C21+C22+C23 -> 426107.06 | D24: =D21+D22+D23 -> 750964.12 | E24: =E21+E22+E23 -> 255242.89
A25: ✓ ประเมินเซลล์: ต้องเท่ากับแถว B7:E7 (มูลค่าที่ลูกค้าได้รับ/ปี) — หากไม่เท่ากันแสดงว่ามีสูตรหลุด | B25: =B24-B7 -> 0 | C25: =C24-C7 -> 0 | D25: =D24-D7 -> 0 | E25: =E24-E7 -> 0
A27: สัดส่วน % ของกำไรที่เพิ่มขึ้น แยกตามแหล่งที่มา (% ของแต่ละไซส์)
A28: แหล่งที่มา | B28: Small | C28: Medium | D28: ใหญ่ | E28: ถ่วงน้ำหนัก (Blended)
A29: 1) จากเวลาที่ประหยัดได้ | B29: =B21/B24 -> 0.10188096 | C29: =C21/C24 -> 0.095828812 | D29: =D21/D24 -> 0.10874909 | E29: =E21/E24 -> 0.10238614
A30: 2) จากความเสี่ยง error ที่หลีกเลี่ยงได้ | B30: =B22/B24 -> 0.82102537 | C30: =C22/C24 -> 0.83165719 | D30: =D22/D24 -> 0.80896009 | E30: =E22/E24 -> 0.82013792
A31: 3) จากเศษเหล็กที่ประหยัดได้ | B31: =B23/B24 -> 0.077093674 | C31: =C23/C24 -> 0.072513995 | D31: =D23/D24 -> 0.082290816 | E31: =E23/E24 -> 0.077475944
A32: รวม (ต้อง = 100%) | B32: =B29+B30+B31 -> 1 | C32: =C29+C30+C31 -> 1 | D32: =D29+D30+D31 -> 1 | E32: =E29+E30+E31 -> 1
A34: กำไรที่เพิ่มขึ้น / ต้นทุนที่ลดลง เป็น % ของงบประมาณโครงการ/ปี (Value-for-money)
A35: แหล่งที่มา | B35: Small | C35: Medium | D35: ใหญ่ | E35: ถ่วงน้ำหนัก (Blended)
A36: งบประมาณโครงการรวม/ปี (งบ/โครงการ × จำนวนโครงการ/ปี) | B36: ='Client — Small'!B7*'Client — Small'!B8 -> 9750000 | C36: ='Client — Medium'!B7*'Client — Medium'!B8 -> 70000000 | D36: ='Client — Large'!B7*'Client — Large'!B8 -> 120000000 | E36: =B36*Assumptions!$B$59+C36*Assumptions!$B$60+D36*Assumptions!$B$61 -> 41350000
A37: กำไรที่เพิ่มขึ้น = ต้นทุนที่ลดลง/ปี (จากแทง 24) | B37: =B24 -> 60119.184 | C37: =C24 -> 426107.06 | D37: =D24 -> 750964.12 | E37: =E24 -> 255242.89
A38: ① % Cost ที่ลดลง/ปี (เทียบกับงบโครงการรวม) | B38: =B37/B36 -> 0.0061660701 | C38: =C37/C36 -> 0.0060872437 | D38: =D37/D36 -> 0.0062580343 | E38: =E37/E36 -> 0.0061727423
A40: กำไรสุทธิเดิมของผู้รับเหมา/ปี (ที่งบนี้, สมมติฐาน margin 12.5% — Assumptions!B81) | B40: =B36*Assumptions!$B$81 -> 1218750 | C40: =C36*Assumptions!$B$81 -> 8750000 | D40: =D36*Assumptions!$B$81 -> 15000000 | E40: =E36*Assumptions!$B$81 -> 5168750
A41: ② % กำไรที่เพิ่มขึ้น/ปี (เทียบกับกำไรสุทธิเดิม — มูลค่าที่ลูกค้ารู้สึกจริงมากกว่า) | B41: =B37/B40 -> 0.049328561 | C41: =C37/C40 -> 0.04869795 | D41: =D37/D40 -> 0.050064274 | E41: =E37/E40 -> 0.049381938
A43: % ประหยัดวัสดุ (เศษเหล็ก) — แยกเฉพาะออกจากรวม
A44: เศษเหล็กแบบมือ → หลัง optimize (วัดจริง) — % ของน้ำหนักเหล็ก, สูตรเดียวเท่ากันทุกไซส์ (Assumptions!B35→B37) | B44: =Assumptions!$B$35 -> 0.065 | C44: =Assumptions!$B$35*(1-Assumptions!$B$37) -> 0.0585
A45: → % ลดเศษเหล็กเชิงกายภาพ (สัมพัทธ์, คงที่ทุกไซส์ — เป็นสัดส่วนเดียวกัน) | B45: =Assumptions!$B$37 -> 0.1
A47: มูลค่าที่ประหยัดจากเศษเหล็ก/ปี (จากแถว 23) | B47: =B23 -> 4634.8087 | C47: =C23 -> 30898.725 | D47: =D23 -> 61797.45 | E47: =E23 -> 19775.184
A48: → % ประหยัดวัสดุ เทียบงบโครงการรวม/ปี (ต่อเนื่องจากงบทั้งหมด) | B48: =B47/B36 -> 0.000475365 | C48: =C47/C36 -> 0.00044141036 | D48: =D47/D36 -> 0.00051497875 | E48: =E47/E36 -> 0.00047823903
A50: % ที่ลดลงได้ของโครงการ — Waste จากความเสี่ยง error ระดับวิศวกรรม/ถอดแบบ (Engineering Site)
A51: โอกาสเกิด error รุนแรง/โครงการ × ความเสียหาย (% ของงบ) — ก่อนใช้ Constistant (คงที่ทุกไซส์) | B51: =Assumptions!$B$29*Assumptions!$B$30 -> 0.005625
...

Sheet AI Infra — Unit Cost
A1: AI Infra & Unit Cost (COGS)
A2: ต้นทุนแปรผนตามเดียว (variable cost) ที่ขับเคลื่อนการตัดสินใจเรื่อง Cost Structure → Pricing Strategy — ทุกช่องเป็นสูตรอ้างอิง Assumptions เป็นหลัก ยกเว้นที่เขียนไว้ชัดเจนเป็นอื่น
A4: สิ่งที่ตัดสินใจ: สฐาปิกรรม AI แบบไหน
A5: โมเดล: Qwen-VL-Max ผ่าน API (Alibaba Cloud DashScope) — ไม่ใช้ self-host GPU ใน base case
A6: เหตุผล #1: หน่อยกว่า GPT-4o-class 6 เท่า | E6: Qwen-VL-Max = $0.41/ล้าน input tokens (Alibaba Cloud) vs GPT-4o = $2.50/ล้าน input + $10.00/ล้าน output tokens — Wikipedia: Qwen (อ้าง Alibaba Cloud pricing), OpenAI pricing docs
A7: เหตุผล #2: ไม่ต้องจอง hardware เผื่อ concurrent user — API scale ตาม request ไม่ใช่ตาม concurrency | E7: ต้นทุนเป็น variable cost ตามจำนวนหน้าแบบที่สแกนจรง ไม่ใช่ fixed cost ตามจำนวนลูกค้าออนไลน์พร้อมกัน — เป็นสิ่งสำคัญที่สุดสำหรับ scalability ของโมเดลนี้
A8: เหตุผล #3: SLA 5 นาที/โครงการ เป็นไปได้จรงด้วย API (ไม่ต้อง self-host) | E8: Inference ต่อหน้าใช้เวลาเพียงสูงวง่จนถึงสิบวินาที — เรียก API แบบ concurrent หลายหน้าในโครงการเดียวก็เสร็จภายใน 5 นาทีได้สบาย — สมมติฐานจาก API latency มาตรฐานของ vision LLM providers
A10: ต้นทุน AI (COGS) ต่อโครงการ และต่อลูกค้า/ปี — แยกตามไซส์ลูกค้า
A11: รายการ | B11: Small | C11: Medium | D11: ใหญ่ | E11: ที่มา/สูตร
A12: จำนวนหน้าแบบ/โครงการ (เฉลี่ย) | B12: =Assumptions!$B$67 -> 50 | C12: =Assumptions!$B$98 -> 250 | D12: =Assumptions!$B$99 -> 666.66667 | E12: Assumptions!B67 (Small=ฐาน), B98/B99 สเกตามสัดส่วนพื้นที่
A13: ต้นทุน AI ต่อหน้า (บาท/หน้า, Qwen-VL-Max) | B13: =Assumptions!$B$66 -> 15 | C13: =Assumptions!$B$66 -> 15 | D13: =Assumptions!$B$66 -> 15 | E13: Assumptions!B66 — อ้างอิงจาก Qwen-VL-Max API rate ($0.41/M input tokens) + buffer สำหรับ output tokens/หน้าซับซ้อน
A14: → ต้นทุน AI ต่อโครงการ (สูตร) | B14: =B12*B13 -> 750 | C14: =C12*C13 -> 3750 | D14: =D12*D13 -> 10000
A15: จำนวนโครงการ/ปี ต่อ 1 ลูกค้า | B15: =Assumptions!$B$43 -> 1.5 | C15: =Assumptions!$B$48 -> 2 | D15: =Assumptions!$B$53 -> 1.5 | E15: Assumptions!B43/B48/B53
A16: → ต้นทุน AI ต่อลูกค้า/ปี (สูตร) | B16: =B14*B15 -> 1125 | C16: =C14*C15 -> 7500 | D16: =D14*D15 -> 15000
A18: กำไรขั้นต้น (Gross Margin) ต่อลูกค้า 1 ราย/ปี — เชื่อมต่อราคาเก็บจริง (Client — Summary)
A19: รายการ | B19: Small | C19: Medium | D19: ใหญ่ | E19: ที่มา/สูตร
A20: ราคา SaaS ที่เก็บ/ปี (รายได้) | B20: ='Client — Summary'!B8 -> 60000 | C20: ='Client — Summary'!C8 -> 84000 | D20: ='Client — Summary'!D8 -> 144000 | E20: Client — Summary!B8:D8
A21: หัก: ต้นทุน AI (COGS) /ปี | B21: =-B16 -> -1125 | C21: =-C16 -> -7500 | D21: =-D16 -> -15000
A22: → กำไรขั้นต้น หลัง AI COGS /ลูกค้า/ปี | B22: =B20+B21 -> 58875 | C22: =C20+C21 -> 76500 | D22: =D20+D21 -> 129000
A23: → % Gross Margin หลัง AI COGS (ก่อนหัก hosting/team/CAC) | B23: =B22/B20 -> 0.98125 | C23: =C22/C20 -> 0.91071429 | D23: =D22/D20 -> 0.89583333 | E23: ชี้เฉพาะต้นทุน AI — ยังไม่รวม hosting/team/CAC (ดูได้ที่ Cost Structure)
A25: Forward-Looking: Self-Host GPU Breakeven — เมื่อไหนจะคุ้มกว่าจ่าย API (ไม่ใช้ใน base case)
A26: ค่าเช่า GPU H20 node (Assumptions!B102) | B26: =Assumptions!$B$102 -> 128 | C26: USD/ชม. | D26: 🟩 อ้างอิงจริง
A27: ค่าเช่า GPU/เดือน (24×30วัน, สมมติฐานว่าเปิดตลอด, อัตราแลกเบี้ยนหน้า/เดือน × 35 บาท) | B27: =B26*24*30*35 -> 3225600 | C27: ฿/เดือน | E27: สมมติฐานอัตราแลกเบี้ยน 35 บาท/USD — เป็นสมมติฐานทีม ปรับได้ตามอัตราแลกเปลี้ยนจริง
A28: → จำนวนหน้าที่ต้องประมวลผล/เดือน เพื่อให้ self-host คุ้มกว่าจ่อย API (breakeven) | B28: =B27/Assumptions!$B$66 -> 215040 | C28: หน้า/เดือน | E28: = ค่า GPU/เดือน ÷ ค่า API/หน้า (Assumptions!B66) — ต่อกว่านี้ self-host จำนวนหน้า/เดือน API ยังถูกกว่า
A29: → เทียบเป็นจำนวนลูกค้า Small เท่ากี่ราย (ข้อมูลอ้างอิง เพื่อ intuition เชิงขนาด) | B29: =B28/(B12/1) -> 4300.8 | C29: ราย (เทียบเดือน) | E29: หากจำนวนลูกค้า Small ส่งหน้าสแกนน้อยกว่าเกณฑ์นี้ต่อเดือน ใช้ API ต่อไป จะกว่าหมดทุน self-host — สูงกว่า SOM ที่ขยีดสุดก็ยงเข้าได้ครอผล (ดู Market—TopDown) — สรุป: ไม่จำเป็นต้อง self-host ในช่วง 5-6 ปีข้างหน้า

Sheet Cost Structure
A1: Cost Structure — 3 Scenario × 5 ปี (ไม่มี dropdown — เห็นทุก Scenario เคียงกันตลอด)
A2: ทุกแทบเป็นสูตรอ้างอิงโดยตรง — Worst/Base/Best เป็น 3 แทวแยกกันชัดเจน ไม่ต้องสลับ dropdown เพื่อดู
A4: 1. ลูกค้าสะสม (ราย) — Y1-3 จาก Market—TopDown, Y4-5 จาก nationwide expansion
A5: Scenario | B5: ปี 1 | C5: ปี 2 | D5: ปี 3 | E5: ปี 4 | F5: ปี 5 | G5: ที่มา/สูตร
A6: Worst | B6: ='Market — TopDown'!$B$13 -> 122 | C6: ='Market — TopDown'!$B$14 -> 213 | D6: ='Market — TopDown'!$B$15 -> 282 | E6: ='Market — TopDown'!$B$26 -> 564 | F6: =E6*Assumptions!$B$117 -> 1128 | G6: Market—TopDown!B13:B15,B26 + ×2.0x Y5 (Assumptions!B117 🟥)
A7: Base | B7: ='Market — TopDown'!$C$13 -> 1086 | C7: ='Market — TopDown'!$C$14 -> 2015 | D7: ='Market — TopDown'!$C$15 -> 2810 | E7: ='Market — TopDown'!$C$26 -> 5620 | F7: =E7*Assumptions!$B$117 -> 11240
A8: Best | B8: ='Market — TopDown'!$D$13 -> 5789 | C8: ='Market — TopDown'!$D$14 -> 11143 | D8: ='Market — TopDown'!$D$15 -> 16098 | E8: ='Market — TopDown'!$D$26 -> 32196 | F8: =E8*Assumptions!$B$117 -> 64392
A10: 2. AI COGS/ปี (blended ทีก mix % จาก AI Infra — Unit Cost)
A11: Scenario | B11: ปี 1 | C11: ปี 2 | D11: ปี 3 | E11: ปี 4 | F11: ปี 5
A12: Worst | B12: =B6*(Assumptions!$B$133*'AI Infra — Unit Cost'!$B$16+Assumptions!$B$134*'AI Infra — Unit Cost'!$C$16+Assumptions!$B$135*'AI Infra — Unit Cost'!$D$16) -> 215025 | C12: =C6*(Assumptions!$C$133*'AI Infra — Unit Cost'!$B$16+Assumptions!$C$134*'AI Infra — Unit Cost'!$C$16+Assumptions!$C$135*'AI Infra — Unit Cost'!$D$16) -> 658968.75 | D12: =D6*(Assumptions!$D$133*'AI Infra — Unit Cost'!$B$16+Assumptions!$D$134*'AI Infra — Unit Cost'!$C$16+Assumptions!$D$135*'AI Infra — Unit Cost'!$D$16) -> 1353600 | E12: =E6*(Assumptions!$E$133*'AI Infra — Unit Cost'!$B$16+Assumptions!$E$134*'AI Infra — Unit Cost'!$C$16+Assumptions!$E$135*'AI Infra — Unit Cost'!$D$16) -> 3278250 | F12: =F6*(Assumptions!$F$133*'AI Infra — Unit Cost'!$B$16+Assumptions!$F$134*'AI Infra — Unit Cost'!$C$16+Assumptions!$F$135*'AI Infra — Unit Cost'!$D$16) -> 7339050
A13: Base | B13: =B7*(Assumptions!$B$133*'AI Infra — Unit Cost'!$B$16+Assumptions!$B$134*'AI Infra — Unit Cost'!$C$16+Assumptions!$B$135*'AI Infra — Unit Cost'!$D$16) -> 1914075 | C13: =C7*(Assumptions!$C$133*'AI Infra — Unit Cost'!$B$16+Assumptions!$C$134*'AI Infra — Unit Cost'!$C$16+Assumptions!$C$135*'AI Infra — Unit Cost'!$D$16) -> 6233906.2 | D13: =D7*(Assumptions!$D$133*'AI Infra — Unit Cost'!$B$16+Assumptions!$D$134*'AI Infra — Unit Cost'!$C$16+Assumptions!$D$135*'AI Infra — Unit Cost'!$D$16) -> 13488000 | E13: =E7*(Assumptions!$E$133*'AI Infra — Unit Cost'!$B$16+Assumptions!$E$134*'AI Infra — Unit Cost'!$C$16+Assumptions!$E$135*'AI Infra — Unit Cost'!$D$16) -> 32666250 | F13: =F7*(Assumptions!$F$133*'AI Infra — Unit Cost'!$B$16+Assumptions!$F$134*'AI Infra — Unit Cost'!$C$16+Assumptions!$F$135*'AI Infra — Unit Cost'!$D$16) -> 73130250
A14: Best | B14: =B8*(Assumptions!$B$133*'AI Infra — Unit Cost'!$B$16+Assumptions!$B$134*'AI Infra — Unit Cost'!$C$16+Assumptions!$B$135*'AI Infra — Unit Cost'!$D$16) -> 10203112 | C14: =C8*(Assumptions!$C$133*'AI Infra — Unit Cost'!$B$16+Assumptions!$C$134*'AI Infra — Unit Cost'!$C$16+Assumptions!$C$135*'AI Infra — Unit Cost'!$D$16) -> 34473656 | D14: =D8*(Assumptions!$D$133*'AI Infra — Unit Cost'!$B$16+Assumptions!$D$134*'AI Infra — Unit Cost'!$C$16+Assumptions!$D$135*'AI Infra — Unit Cost'!$D$16) -> 77270400 | E14: =E8*(Assumptions!$E$133*'AI Infra — Unit Cost'!$B$16+Assumptions!$E$134*'AI Infra — Unit Cost'!$C$16+Assumptions!$E$135*'AI Infra — Unit Cost'!$D$16) -> 1.8713925e+08 | F14: =F8*(Assumptions!$F$133*'AI Infra — Unit Cost'!$B$16+Assumptions!$F$134*'AI Infra — Unit Cost'!$C$16+Assumptions!$F$135*'AI Infra — Unit Cost'!$D$16) -> 4.1895045e+08
A16: ทีมงาน+Hosting+Overhead เหมาเหมือน (flat, ทุก Scenario ก่อน Y4-5) = Assumptions!B63×B64×12 + B65×12 + B69×12 | B16: =Assumptions!$B$63*Assumptions!$B$64*12+Assumptions!$B$65*12+Assumptions!$B$69*12 -> 3096000
A18: 3. ต้นทุนคงที่+CAC/ปี (Y1-3=flat+CAC ตามลูกค้าใหม่, Y4-5=scale ตาม ratio ของ scenarioเอง)
A19: Scenario | B19: ปี 1 | C19: ปี 2 | D19: ปี 3 | E19: ปี 4 | F19: ปี 5 | G19: ที่มา/สูตร
A20: Worst | B20: =$B$16+B6*Assumptions!$B$68 -> 3462000 | C20: =$B$16+(C6-B6)*Assumptions!$B$68 -> 3369000 | D20: =$B$16+(D6-C6)*Assumptions!$B$68 -> 3303000 | E20: =$B$16*(E6/D6)+(E6-D6)*Assumptions!$B$68 -> 7038000 | F20: =$B$16*(F6/D6)+(F6-E6)*Assumptions!$B$68 -> 14076000 | G20: Y4-5: ทีมงาน scale ตามอัตราส่วนลูกค้าของ scenarioเดียวกัน (ไม่ข้อง dropdown) 🟥
A21: Base | B21: =$B$16+B7*Assumptions!$B$68 -> 6354000 | C21: =$B$16+(C7-B7)*Assumptions!$B$68 -> 5883000 | D21: =$B$16+(D7-C7)*Assumptions!$B$68 -> 5481000 | E21: =$B$16*(E7/D7)+(E7-D7)*Assumptions!$B$68 -> 14622000 | F21: =$B$16*(F7/D7)+(F7-E7)*Assumptions!$B$68 -> 29244000
A22: Best | B22: =$B$16+B8*Assumptions!$B$68 -> 20463000 | C22: =$B$16+(C8-B8)*Assumptions!$B$68 -> 19158000 | D22: =$B$16+(D8-C8)*Assumptions!$B$68 -> 17961000 | E22: =$B$16*(E8/D8)+(E8-D8)*Assumptions!$B$68 -> 54486000 | F22: =$B$16*(F8/D8)+(F8-E8)*Assumptions!$B$68 -> 108972000
A24: 4. → รวมต้นทุนบริษัททั้นหมด/ปี (AI COGS + Fixed+CAC)
A25: Scenario | B25: ปี 1 | C25: ปี 2 | D25: ปี 3 | E25: ปี 4 | F25: ปี 5
A26: Worst | B26: =B12+B20 -> 3677025 | C26: =C12+C20 -> 4027968.8 | D26: =D12+D20 -> 4656600 | E26: =E12+E20 -> 10316250 | F26: =F12+F20 -> 21415050
A27: Base | B27: =B13+B21 -> 8268075 | C27: =C13+C21 -> 12116906 | D27: =D13+D21 -> 18969000 | E27: =E13+E21 -> 47288250 | F27: =F13+F21 -> 1.0237425e+08
A28: Best | B28: =B14+B22 -> 30666112 | C28: =C14+C22 -> 53631656 | D28: =D14+D22 -> 95231400 | E28: =E14+E22 -> 2.4162525e+08 | F28: =F14+F22 -> 5.2792245e+08

Sheet Pricing Strategy
A1: Pricing Strategy — ราคาที่ผ่านการ validate ด้วยต้นทุนจริง
A2: ตรวจสอบว่าราคาที่เก็บจริง (Client — Summary/Assumptions) คุ้มค่าเหนือต้นทุนจริงเท่าไหร เทียบกับคู่แข่ง และเทียบกับ ROI ที่ลูกค้าได้จริง
A4: 1. Cost-Plus Check — ราคาเก็บจริง เทียบ AI COGS + ส่วนแบ่งต้นทุนคงที่
A5: รายการ | B5: Small | C5: Medium | D5: ใหญ่ | E5: ที่มา/สูตร
A6: ราคา SaaS ที่เก็บจริง/เดือน | B6: =Assumptions!$B$55 -> 5000 | C6: =Assumptions!$B$56 -> 7000 | D6: =Assumptions!$B$57 -> 12000 | E6: Assumptions!B55:B57
A7: ต้นทุน AI (COGS)/เดือน | B7: ='AI Infra — Unit Cost'!$B$16/12 -> 93.75 | C7: ='AI Infra — Unit Cost'!$C$16/12 -> 625 | D7: ='AI Infra — Unit Cost'!$D$16/12 -> 1250
A8: ส่วนแบ่งต้นทุนคงที่/เดือน (จาก Cost Structure, Base Case ปี 3) | B8: ='Cost Structure'!$D$21/'Cost Structure'!$D$7/12 -> 162.54448 | C8: =B8 -> 162.54448 | D8: =B8 -> 162.54448 | E8: เฌลี่ยเท่ากับทุกไซส์ (เป็น fixed cost ส่วนกลาง) — เป็น simplification ทีม ยังไม่ได้ allocate ตามการใช้งานจริง
A9: → ต้นทุนเต็ม/เดือน (AI COGS + ส่วนแบ่งคงที่) | B9: =B7+B8 -> 256.29448 | C9: =C7+C8 -> 787.54448 | D9: =D7+D8 -> 1412.5445
A10: → กำไรขั้นต้น/เดือน (ราคา − ต้นทุนเต็ม) | B10: =B6-B9 -> 4743.7055 | C10: =C6-C9 -> 6212.4555 | D10: =D6-D9 -> 10587.456
A11: → % Margin ที่ราคานี้เหลือหลังหักทุกต้นทุนเต็ม (Full-Cost Margin) | B11: =B10/B6 -> 0.9487411 | C11: =C10/C6 -> 0.88749365 | D11: =D10/D6 -> 0.88228796
A13: 2. Value-Based Check — ROI ที่ลูกค้าได้จริง (Client — Summary)
A14: รายการ | B14: Small | C14: Medium | D14: ใหญ่ | E14: ที่มา/สูตร
A15: มูลค่าที่ลูกค้าได้รับ/ปี (เวลา+error+เศษเหล็ก) | B15: ='Client — Small'!$B$25 -> 60119.184 | C15: ='Client — Medium'!$B$25 -> 426107.06 | D15: ='Client — Large'!$B$25 -> 750964.12 | E15: Client — Small/Medium/Large!B25
A16: ราคาที่เก็บ/ปี | B16: =B6*12 -> 60000 | C16: =C6*12 -> 84000 | D16: =D6*12 -> 144000
A17: → ROI ที่ลูกค้าได้ (มูลค่า ÷ ราคา) | B17: =B15/B16 -> 1.0019864 | C17: =C15/C16 -> 5.0727031 | D17: =D15/D16 -> 5.2150286 | E17: เกณฑ์ mental: หาก ROI < 3x มีความเสี่ยงเรื่อง WTP เนื่องจากไม่มี survey จริง (ดู Assumptions — จุดเตือน)
A18: ⚠️ Small segment ROI ≈ 1.0x — มูลค่าที่ลูกค้าได้เกือบเท่ากับราคาพอดี — ความเสี่ยงเรื่อง churn สูงกว่า Medium/ใหญ่ (5.1x/5.2x) | E18: สอดคล้องกับ BUILK precedent (Assumptions A92-95) — กลุ่ม micro-SME เป็นกลุ่มที่ churn สูงสุดเสมอ — เสนอ: พิจารณาลดราคา Small หรือเพิ่มมูลค่า (เช่น batchหลายเจ้าของ/เดือน) เพื่อเพิ่ม ROI — เป็นข้อเสนอองค์การ ไม่ใช่การเปลี่นราคาอัตโมติ
A19: 3. Competitive Benchmark (Competitors!D10:D14)
A20: CivilProMax (ไทย, ใกล้เคียงที่สุด) | B20: =Competitors!$D$13 -> ฿1,050/ปี | E20: ชำระคนเดียว ไม่มี BBS ออกอีกหน้า — เราเก็บเป็นรายเดือนแต่สูงกว่าเยอะ—เหมาะสมเมื่อคนจ่ายต่อเดือนไม่หวงกับต้องจ่ายก้อนเต็มปีเหมือน CivilProMax
A21: Togal.AI (โลก, benchmark สำหรับ global player) | B21: =Competitors!$D$10 -> $299/user/เดือน (Growth), Custom (Enterprise) | E21: $299/user/เดือน ≈ 10,465 บาท/เดือน (@35฿/$) — สูงกว่าราคาเรา 2–10 เท่า — เหมาะกับตลาด SME ไทยเพราะ SME จ่ายไหวกว่ามากไม่ได้
A22: → ตำแหน่งราคา: สูงกว่า CivilProMax (เหมาะสม — เรามี BBS อื่นๆที่เขาไม่มี), ต่ำกว่า Togal.AI มาก (เป็นเหตุที่ทำให้ SME ไทยเข้าถึงได้)

Sheet 5-Year Projection
A1: 5-Year Financial Projection — Worst / Base / Best
A2: ลูกค้า (Market — TopDown) × ARPU (Client — Summary) − ต้นทุน (Cost Structure, AI Infra) = กำไร—ทุกช่องเป็นสูตรอ้างอิง ปี 4-5 ขยายด้วยอัตราเติบโต 🟥 (Assumptions!B117)
A4: ลูกค้าสะสม (ราย) | B4: ปี 1 | C4: ปี 2 | D4: ปี 3 | E4: ปี 4 | F4: ปี 5 | G4: ที่มา/สูตร
A5: Worst | B5: ='Market — TopDown'!B13 -> 122 | C5: ='Market — TopDown'!B14 -> 213 | D5: ='Market — TopDown'!B15 -> 282 | E5: ='Market — TopDown'!B26 -> 564 | F5: =E5*Assumptions!$B$117 -> 1128 | G5: Yr1-3='Market—TopDown'!B13:B15, Yr4=B26, Yr5=Yr4×2x 🟥
A6: Base | B6: ='Market — TopDown'!C13 -> 1086 | C6: ='Market — TopDown'!C14 -> 2015 | D6: ='Market — TopDown'!C15 -> 2810 | E6: ='Market — TopDown'!C26 -> 5620 | F6: =E6*Assumptions!$B$117 -> 11240 | G6: ⚠️ ปี 4 กระโดดขึ้นเพราะ Market—TopDown เปลี่ยนฐานการคำนวณเป็น 'SME ทีเข้าถึงได้จริงทั้งประเทศ' (ขยายจาก BMR+6 จังหวัด) — เป็น modeling choice เดีมของชีต ไม่ได้เปลี่ยน
A7: Best | B7: ='Market — TopDown'!D13 -> 5789 | C7: ='Market — TopDown'!D14 -> 11143 | D7: ='Market — TopDown'!D15 -> 16098 | E7: ='Market — TopDown'!D26 -> 32196 | F7: =E7*Assumptions!$B$117 -> 64392
A9: รายได้ (ARR, บาท)
A10: Worst | B10: =B5*'Client — Summary'!$B$69 -> 4964424 | C10: =C5*'Client — Summary'!$C$69 -> 10843830 | D10: =D5*'Client — Summary'!$D$69 -> 22165200 | E10: =E5*'Client — Summary'!$E$69 -> 47376000 | F10: =F5*'Client — Summary'!$F$69 -> 99489600 | G10: ลูกค้า × ARPU ที่ถ่วงน้ำหนัก (Client—Summary!E8 Yr1-3, E17 Yr4-5 — ขยายทั้งประเทศ ARPU สูงกว่า)
A11: Base | B11: =B6*'Client — Summary'!$B$69 -> 44191512 | C11: =C6*'Client — Summary'!$C$69 -> 102583650 | D11: =D6*'Client — Summary'!$D$69 -> 220866000 | E11: =E6*'Client — Summary'!$E$69 -> 472080000 | F11: =F6*'Client — Summary'!$F$69 -> 991368000
A12: Best | B12: =B7*'Client — Summary'!$B$69 -> 235565988 | C12: =C7*'Client — Summary'!$C$69 -> 567290130 | D12: =D7*'Client — Summary'!$D$69 -> 1265302800 | E12: =E7*'Client — Summary'!$E$69 -> 2704464000 | F12: =F7*'Client — Summary'!$F$69 -> 5679374400
A14: ต้นทุนรวม (AI COGS + Fixed, บาท)
A15: Worst | B15: ='Cost Structure'!$B$26 -> 3677025 | C15: ='Cost Structure'!$C$26 -> 4027968.8 | D15: ='Cost Structure'!$D$26 -> 4656600 | E15: ='Cost Structure'!$E$26 -> 10316250 | F15: ='Cost Structure'!$F$26 -> 21415050 | G15: Yr1-3: AI COGS(blended)+flat team/hosting/overhead+CAC×ลูกค้าใหม่. Yr4-5: ใช้อัตรา fixed-cost/ลูกค้าที่ปี 3 (Base) เพื่อสเกตหลังเลิก fixed-team-flat — 🟥 สมมติฐาน scale-up team ต้อง revisit
A16: Base | B16: ='Cost Structure'!$B$27 -> 8268075 | C16: ='Cost Structure'!$C$27 -> 12116906 | D16: ='Cost Structure'!$D$27 -> 18969000 | E16: ='Cost Structure'!$E$27 -> 47288250 | F16: ='Cost Structure'!$F$27 -> 1.0237425e+08
A17: Best | B17: ='Cost Structure'!$B$28 -> 30666112 | C17: ='Cost Structure'!$C$28 -> 53631656 | D17: ='Cost Structure'!$D$28 -> 95231400 | E17: ='Cost Structure'!$E$28 -> 2.4162525e+08 | F17: ='Cost Structure'!$F$28 -> 5.2792245e+08
A19: → กำไรขั้นต้น (รายได้ − ต้นทุนรวม, บาท)
A20: Worst | B20: =B10-B15 -> 1287399 | C20: =C10-C15 -> 6815861.2 | D20: =D10-D15 -> 17508600 | E20: =E10-E15 -> 37059750 | F20: =F10-F15 -> 78074550
A21: Base | B21: =B11-B16 -> 35923437 | C21: =C11-C16 -> 90466744 | D21: =D11-D16 -> 201897000 | E21: =E11-E16 -> 424791750 | F21: =F11-F16 -> 888993750
A22: Best | B22: =B12-B17 -> 2.0489988e+08 | C22: =C12-C17 -> 5.1365847e+08 | D22: =D12-D17 -> 1170071400 | E22: =E12-E17 -> 2462838750 | F22: =F12-F17 -> 5151451950
A24: → % Net Margin (Base case) | B24: =B21/B11 -> 0.81290355 | C24: =C21/C11 -> 0.88188268 | D24: =D21/D11 -> 0.91411535 | E24: =E21/E11 -> 0.89983001 | F24: =F21/F11 -> 0.89673436
A26: LTV:CAC (Base case, สมมติฐาน avg customer lifetime 3ปี) | B26: =('Client — Summary'!$E$8*3)/Assumptions!$B$68 -> 78.6 | G26: LTV=ARPU×3ปี(🟥สมมติฐานทีม—ไม่มี churn data จริง), CAC=Assumptions!B68 — คนหาจีดี SaaS benchmark คือ >3x

Sheet Business Model — Revenue
A1: Business Model — Revenue
A2: รายได้บริษัท 3 ปี ทั้ง Scenario ที่ใช้งานอยู่ (dropdown) และเทียบ Worst/Base/Best เคียงกัน
A4: รายการ | B4: ปีที่ 1 | C4: ปีที่ 2 | D4: ปีที่ 3 | E4: ปีที่ 4
A5: ลูกค้าสะสม — Scenario ที่ใช้งานอยู่ (ราย) | B5: =IF(Assumptions!$B$16="Worst",'Market — TopDown'!B13,IF(Assumptions!$B$16="Best",'Market — TopDown'!D13,'Market — TopDown'!C13)) -> 5789 | C5: =IF(Assumptions!$B$16="Worst",'Market — TopDown'!B14,IF(Assumptions!$B$16="Best",'Market — TopDown'!D14,'Market — TopDown'!C14)) -> 11143 | D5: =IF(Assumptions!$B$16="Worst",'Market — TopDown'!B15,IF(Assumptions!$B$16="Best",'Market — TopDown'!D15,'Market — TopDown'!C15)) -> 16098 | E5: ='Market — TopDown'!B29 -> 0
A6: ลูกค้าใหม่ที่เพิ่มขึ้นในปีนั้น (ราย) | B6: =B5 -> 5789 | C6: =C5-B5 -> 5354 | D6: =D5-C5 -> 4955 | E6: =E5-D5 -> -16098
A7: รายได้เฉลี่ย/ลูกค้า/ปี (ถ่วงน้ำหนัก) | B7: ='Client — Summary'!$B$69 -> 40692 | C7: ='Client — Summary'!$C$69 -> 50910 | D7: ='Client — Summary'!$D$69 -> 78600 | E7: ='Client — Summary'!E17 -> 94320
A8: รวมรายได้ (Scenario ที่ใช้งานอยู่) | B8: =B5*B7 -> 235565988 | C8: =C5*C7 -> 567290130 | D8: =D5*D7 -> 1265302800 | E8: =E5*E7 -> 0
A10: เทียบรายได้ปีที่ 3 — Worst / Base / Best (ใช้ลูกค้าจากตาราง SOM เทียบ 3 Scenario)
B11: Worst | C11: Base | D11: Best
A12: ลูกค้าสะสมปีที่ 3 (ราย) | B12: ='Market — TopDown'!B15 -> 282 | C12: ='Market — TopDown'!C15 -> 2810 | D12: ='Market — TopDown'!D15 -> 16098
A13: รายได้ปีที่ 3 | B13: =B12*'Client — Summary'!E8 -> 22165200 | C13: =C12*'Client — Summary'!E8 -> 220866000 | D13: =D12*'Client — Summary'!E8 -> 1265302800
A15: เทียบรายได้ปีที่ 4 — Worst / Base / Best (เป้า Best = 300 ล้านบาท จุดเริ่มเติบโต 2×/ปี → 1,200M ปี 6)
A16: ปีที่ 4 | B16: Worst | C16: Base | D16: Best
A17: ลูกค้าสะสมปีที่ 4 (ราย) | B17: =IF(Assumptions!$B$16="Worst",'Market — TopDown'!B26,IF(Assumptions!$B$16="Best",'Market — TopDown'!D26,'Market — TopDown'!C26)) -> 32196 | C17: ='Market — TopDown'!C26 -> 5620 | D17: ='Market — TopDown'!D26 -> 32196
A18: รายได้ปีที่ 4 | B18: =B17*'Client — Summary'!E17 -> 3036726720 | C18: =C17*'Client — Summary'!E17 -> 530078400 | D18: =D17*'Client — Summary'!E17 -> 3036726720
A19: เซลล์เทียบ: เป้า 300 ล้านบาท (Best-case ปีที่ 4) — ช่องห่างที่เหลือ | D19: =300000000-D18 -> -2736726720
A21: เทียบรายได้ปีที่ 5 (Best-case, เป้า = 2×ปีที่4 = 600 ล้านบาท)
A22: ลูกค้าสะสมปีที่ 5 (ราย) | B22: ='Market — TopDown'!B34 -> 6361
A23: รายได้ปีที่ 5 | B23: =B22*'Client — Summary'!E17 -> 599969520
A24: เซลล์เทียบ: เป้า 600 ล้านบาท — ช่องห่างที่เหลือ | B24: =600000000-B23 -> 30480
A26: เทียบรายได้ปีที่ 6 (Best-case, เป้า = 4×ปีที่4 = 1,200 ล้านบาท)
A27: ลูกค้าสะสมปีที่ 6 (ราย) | B27: ='Market — TopDown'!B35 -> 12723
A28: รายได้ปีที่ 6 | B28: =B27*'Client — Summary'!E17 -> 1200033360
A29: เซลล์เทียบ: เป้า 1,200 ล้านบาท — ช่องห่างที่เหลือ | B29: =1200000000-B28 -> -33360

Sheet Business Model — Cost
A1: Business Model — Cost
A2: ต้นทุนบริษัท 3 ปี — ⚠️ ทุกบรรทัดอ้างอิงสมมติฐานใน Assumptions (ไม่มีตัวเลขต้นทุนจริงในโปรเจกต์นี้)
A4: รายการ | B4: ปีที่ 1 | C4: ปีที่ 2 | D4: ปีที่ 3 | E4: ปีที่ 4 (Best-case)
A5: ทีมงาน (เงินเดือน × 12) | B5: =Assumptions!$B$63*Assumptions!$B$64*12 -> 2880000 | C5: =Assumptions!$B$63*Assumptions!$B$64*12 -> 2880000 | D5: =Assumptions!$B$63*Assumptions!$B$64*12 -> 2880000 | E5: =Assumptions!$B$79*Assumptions!$B$64*12 -> 4320000
A6: Hosting/Infra | B6: =Assumptions!$B$65*12 -> 96000 | C6: =Assumptions!$B$65*12 -> 96000 | D6: =Assumptions!$B$65*12 -> 96000 | E6: =Assumptions!$B$65*12 -> 96000
A7: ค่าใช้จ่ายทั่วไป | B7: =Assumptions!$B$69*12 -> 120000 | C7: =Assumptions!$B$69*12 -> 120000 | D7: =Assumptions!$B$69*12 -> 120000 | E7: =Assumptions!$B$69*12 -> 120000
A8: ต้นทุน AI (ต่อการสแกนแบบ) | B8: ='Business Model — Revenue'!B5*Assumptions!$B$67*Assumptions!$B$66 -> 4341750 | C8: ='Business Model — Revenue'!C5*Assumptions!$B$67*Assumptions!$B$66 -> 8357250 | D8: ='Business Model — Revenue'!D5*Assumptions!$B$67*Assumptions!$B$66 -> 12073500 | E8: ='Business Model — Revenue'!D17*Assumptions!$B$67*Assumptions!$B$66 -> 24147000
A9: ต้นทุนหาลูกค้าใหม่ (CAC × ลูกค้าใหม่) | B9: ='Business Model — Revenue'!B6*Assumptions!$B$68 -> 17367000 | C9: ='Business Model — Revenue'!C6*Assumptions!$B$68 -> 16062000 | D9: ='Business Model — Revenue'!D6*Assumptions!$B$68 -> 14865000 | E9: =('Business Model — Revenue'!D17-'Business Model — Revenue'!D12)*Assumptions!$B$68 -> 48294000
A11: รวมต้นทุน | B11: =B5+B6+B7+B8+B9 -> 24804750 | C11: =C5+C6+C7+C8+C9 -> 27515250 | D11: =D5+D6+D7+D8+D9 -> 30034500 | E11: =E5+E6+E7+E8+E9 -> 76977000
A13: ต้นทุนปีที่ 5/6 (Best-case, ทีมขยายตาม Assumptions!B84/B85)
A14: รายการ | B14: ปีที่ 5 | C14: ปีที่ 6
A15: ทีมงาน (เงินเดือน × 12) | B15: =Assumptions!$B$84*Assumptions!$B$64*12 -> 7200000 | C15: =Assumptions!$B$85*Assumptions!$B$64*12 -> 12600000
A16: Hosting/Infra | B16: =Assumptions!$B$65*12 -> 96000 | C16: =Assumptions!$B$65*12 -> 96000
A17: ค่าใช้จ่ายทั่วไป | B17: =Assumptions!$B$69*12 -> 120000 | C17: =Assumptions!$B$69*12 -> 120000
A18: ต้นทุน AI (ต่อการสแกนแบบ) | B18: ='Business Model — Revenue'!B22*Assumptions!$B$67*Assumptions!$B$66 -> 4770750 | C18: ='Business Model — Revenue'!B27*Assumptions!$B$67*Assumptions!$B$66 -> 9542250
A19: ต้นทุนหาลูกค้าใหม่ (CAC × ลูกค้าใหม่) | B19: =('Business Model — Revenue'!B22-'Market — TopDown'!D26)*Assumptions!$B$68 -> -77505000 | C19: =('Business Model — Revenue'!B27-'Market — TopDown'!B34)*Assumptions!$B$68 -> 19086000
A20: รวมต้นทุน | B20: =SUM(B15:B19) -> -65318250 | C20: =SUM(C15:C19) -> 41444250

Sheet Business Model — Profit
A1: Business Model — Profit
A2: Revenue − Cost = Profit, 3 ปี, Scenario ที่ใช้งานอยู่ + เทียบ Worst/Base/Best ปีที่ 3 — ดึงเลขนี้ไปใช้ในสไลด์ Financial ได้เลย
A4: รายการ | B4: ปีที่ 1 | C4: ปีที่ 2 | D4: ปีที่ 3
A5: รายได้ (Scenario ที่ใช้งานอยู่) | B5: ='Business Model — Revenue'!B8 -> 235565988 | C5: ='Business Model — Revenue'!C8 -> 567290130 | D5: ='Business Model — Revenue'!D8 -> 1265302800
A6: ต้นทุน | B6: ='Business Model — Cost'!B11 -> 24804750 | C6: ='Business Model — Cost'!C11 -> 27515250 | D6: ='Business Model — Cost'!D11 -> 30034500
A7: กำไร (Profit) | B7: =B5-B6 -> 210761238 | C7: =C5-C6 -> 539774880 | D7: =D5-D6 -> 1235268300
A8: Margin % | B8: =IF(B5=0,0,B7/B5) -> 0.89470148 | C8: =IF(C5=0,0,C7/C5) -> 0.95149704 | D8: =IF(D5=0,0,D7/D5) -> 0.97626299
A10: หัวข้อสไลด์: เทียบปีที่ 3 — Worst / Base / Best
B11: Worst | C11: Base | D11: Best
A12: รายได้ปีที่ 3 | B12: ='Business Model — Revenue'!B13 -> 22165200 | C12: ='Business Model — Revenue'!C13 -> 220866000 | D12: ='Business Model — Revenue'!D13 -> 1265302800
A13: ต้นทุนปีที่ 3 (ประมาณ — ทีม/hosting/overhead ใช้โครงสร้างเดียวกับ Base, AI cost + CAC สเกลตามลูกค้าจริงของแต่ละ Scenario) | B13: ='Business Model — Cost'!D5+'Business Model — Cost'!D6+'Business Model — Cost'!D7+'Market — TopDown'!B15*Assumptions!$B$67*Assumptions!$B$66+('Market — TopDown'!B15-'Market — TopDown'!B14)*Assumptions!$B$68 -> 3514500 | C13: ='Business Model — Cost'!D5+'Business Model — Cost'!D6+'Business Model — Cost'!D7+'Market — TopDown'!C15*Assumptions!$B$67*Assumptions!$B$66+('Market — TopDown'!C15-'Market — TopDown'!C14)*Assumptions!$B$68 -> 7588500 | D13: ='Business Model — Cost'!D5+'Business Model — Cost'!D6+'Business Model — Cost'!D7+'Market — TopDown'!D15*Assumptions!$B$67*Assumptions!$B$66+('Market — TopDown'!D15-'Market — TopDown'!D14)*Assumptions!$B$68 -> 30034500
A14: กำไรปีที่ 3 | B14: =B12-B13 -> 18650700 | C14: =C12-C13 -> 213277500 | D14: =D12-D13 -> 1235268300
A15: Margin % ปีที่ 3 | B15: =IF(B12=0,0,(B12-B13)/B12) -> 0.84144064 | C15: =IF(C12=0,0,(C12-C13)/C12) -> 0.96564206 | D15: =IF(D12=0,0,(D12-D13)/D12) -> 0.97626299
A17: หมายเหตุ: ทีมงาน/hosting/overhead ใช้ตัวเลขเดียวกันทั้ง 3 Scenario (ไม่ได้ปรับขนาดทีมตามยอดขาย) ส่วน AI cost และ CAC ปรับตามจำนวนลูกค้าจริงของแต่ละ Scenario แล้ว — ปรับ headcount เองใน Assumptions ได้ถ้าต้องการให้ทีมโตตามยอดขาย Best case
A20: เทียบกำไรปีที่ 4 (Best-case, ขยายทั่วประเทศ+upsell) — ดูโครงสร้างเต็มที่ Business Model — Revenue/Cost แท็บ 15-19 และ E4-E11
A21: รายได้ปีที่ 4 (Best) | B21: ='Business Model — Revenue'!D18 -> 3036726720
A22: ต้นทุนปีที่ 4 (Best, ทีมขยายเป็น 12 คนตาม Assumptions) | B22: ='Business Model — Cost'!E11 -> 76977000
A23: กำไรปีที่ 4 | B23: =B21-B22 -> 2959749720
A24: Margin % ปีที่ 4 | B24: =IF(B21=0,0,B23/B21) -> 0.97465132
A26: เทียบกำไรปีที่ 5/6 (Best-case) — ดูโครงสร้างเต็มที่ Business Model — Revenue แถว 21-29 และ Cost แถว 13-20
A27: รายการ | B27: ปีที่ 5 | C27: ปีที่ 6
A28: รายได้ | B28: ='Business Model — Revenue'!B23 -> 599969520 | C28: ='Business Model — Revenue'!B28 -> 1200033360
A29: ต้นทุน | B29: ='Business Model — Cost'!B20 -> -65318250 | C29: ='Business Model — Cost'!C20 -> 41444250
A30: กำไร | B30: =B28-B29 -> 665287770 | C30: =C28-C29 -> 1158589110
A31: Margin % | B31: =IF(B28=0,0,B30/B28) -> 1.1088693 | C31: =IF(C28=0,0,C30/C28) -> 0.96546409

Sheet Sustainability Impact
A1: Sustainability Impact — เทียบมูลค่าคาร์บอนที่ประหยัดได้จริง
A2: 3 กลไกรของความยีนยง: (1) เหล็ก/BBS ออปติไมซ์ — สูตรอ้างจากการวดจรง (2) เลือกวัสดุคาร์บอนต่ำใน BOQ — 🟥 สมมติฐานทีม (3) Planner ลดเวลา/ความสูญเปล่า — 🟥 สมมติฐานทีม — มีเฉพาะเหล็ก/BBS เท่านั้นที่สอดคล้องกับการวัดจริงในระบบ อีก 2 กลไกเป็นสมมติฐานทีมชัดเจน—ชี้ช่องเพื่อ validate ช่องทางต่อไป ไม่ควรนำเสนอ ROI เป็น fact จนกว่าเก็บ data จริง
A4: 1. เหล็ก/BBS Optimization → CO2 ที่ลดได้ 🟩 อ้างอิงจากสูตรที่มีอยู่จริง
A5: รายการ | B5: Small | C5: Medium | D5: ใหญ่ | E5: ที่มา/สูตร
A6: เสdียกเหล็กที่ลดได้/โครงการ (กก.) — เสdียกเหล็กมือ − กาลีวัน optimize จริง | B6: ='Client — Small'!$B$18-'Client — Small'!$B$20 -> 143.715 | C6: ='Client — Medium'!$B$18-'Client — Medium'!$B$20 -> 718.575 | D6: ='Client — Large'!$B$18-'Client — Large'!$B$20 -> 1916.2 | E6: Client — Small/Medium/Large!B18−B20 (เสdียกเหล็กแบบมือ − หลัง optimize วัดจริง)
A7: → CO2 ที่ลดได้/โครงการ (× 1.99 kgCO2e/kg) | B7: =B6*Assumptions!$B$105 -> 285.99285 | C7: =C6*Assumptions!$B$105 -> 1429.9642 | D7: =D6*Assumptions!$B$105 -> 3813.238
A8: จำนวนโครงการ/ปี ต่อลูกค้า | B8: =Assumptions!$B$43 -> 1.5 | C8: =Assumptions!$B$48 -> 2 | D8: =Assumptions!$B$53 -> 1.5
A9: → CO2 ที่ลดได้/ลูกค้า/ปี | B9: =B7*B8 -> 428.98927 | C9: =C7*C8 -> 2859.9285 | D9: =D7*D8 -> 5719.857
A11: 2. เลือกวัสดุคาร์บอนต่ำใน BOQ → CO2 ที่ลดได้ 🟥 สมมติฐานทีม — จำเป็นต้อง validate
A12: รายการ | B12: Small | C12: Medium | D12: ใหญ่ | E12: ที่มา/สูตร
A13: ปริมาณคอนกรีต/โครงการ (พื้นที่ × m3/ตร.ม.) | B13: ='Client — Small'!$B$6*Assumptions!$B$111 -> 105 | C13: ='Client — Medium'!$B$6*Assumptions!$B$111 -> 525 | D13: ='Client — Large'!$B$6*Assumptions!$B$111 -> 1400 | E13: Client!B6 (พื้นที่) × Assumptions!B111 🟥
A14: → น้ำหนักคอนกรีต (× 2,400 kg/m3) | B14: =B13*Assumptions!$B$107 -> 252000 | C14: =C13*Assumptions!$B$107 -> 1260000 | D14: =D13*Assumptions!$B$107 -> 3360000
A15: × % ลูกค้าเลือก mix GGBS 🟥 (Assumptions!B109) | B15: =Assumptions!$B$109 -> 0.2 | C15: =Assumptions!$B$109 -> 0.2 | D15: =Assumptions!$B$109 -> 0.2
A16: × ค่า embodied carbon ของคอนกรีตมาตรฐาน 🟨 (Assumptions!B106) | B16: =Assumptions!$B$106 -> 0.11 | C16: =Assumptions!$B$106 -> 0.11 | D16: =Assumptions!$B$106 -> 0.11
A17: × % ลด CO2 เมื่อเลือก mix นี้ 🟥 (Assumptions!B110) | B17: =Assumptions!$B$110 -> 0.2 | C17: =Assumptions!$B$110 -> 0.2 | D17: =Assumptions!$B$110 -> 0.2
A18: → CO2 ที่ลดได้/โครงการ (หากเลือก) | B18: =B14*B15*B16*B17 -> 1108.8 | C18: =C14*C15*C16*C17 -> 5544 | D18: =D14*D15*D16*D17 -> 14784
A19: → CO2 ที่ลดได้/ลูกค้า/ปี | B19: =B18*B8 -> 1663.2 | C19: =C18*C8 -> 11088 | D19: =D18*D8 -> 22176
